Workbook

Sheet JAリスト
A1: 企業名 | B1: ホームページ | C1: 住所 | D1: 電話番号 | E1: 地域の農業特徴・特産品情報 | F1: 想定される課題・アプローチのポイント | G1: 提案の切り口（自社サービス・強み） | H1: 担当部署 | I1: 役職 | J1: 担当者 | K1: 活用状況 | L1: 実習人数 | M1: 実習_国籍 | N1: 特技人数 | O1: 特技_国籍 | P1: 既存状況 | Q1: 営業状況 | R1: ステータス | S1: 進捗 | T1: 初回訪問日 | U1: 最終コンタクト日 | V1: 最終経過日数 | W1: 訪問履歴 | X1: 最終アクション（日付・結果/詳細） | Y1: 日付 | Z1: 行動 | AA1: 次回アクション予定 | AB1: 予定日 | AC1: 連携元 | AD1: 連携元所属 | AE1: 連携者 | AF1: 連携先 | AG1: 担当所属 | AH1: 営業担当 | AI1: 受注日 | AJ1: 受注内容 | AK1: 配属予定日 | AL1: 受注_国籍 | AM1: 受注_人数 | AN1: 状況 | AO1: 加電回数 | AP1: 最終加電日 | AQ1: 最終結果
A2: JA道央 | B2: https://www.ja-douou.or.jp/ | C2: 北海道恵庭市島松仲町2丁目10-1 (〒061-1352) ※本所 | D2: 0123-36-1122 | E2: 都市近郊型の稲作、野菜、花き栽培が盛ん。 | F2: 多品目栽培により一年を通して労働力が必要。都市部近くのため人材の定着は比較的見込める。 | G2: 補助金採択を条件とした完全成果報酬型を提示し、複数農家での人材シェアリングを提案。 | AG2: BREXA CrossBorder | AH2: 武田 悦郎 | AO2: =COUNTIFS(加電履歴!$F:$F,A2,加電履歴!$E:$E,"JAリスト") | AP2: =IFERROR(IF(COUNTIFS(加電履歴!$F:$F,A2,加電履歴!$E:$E,"JAリスト")=0,"",MAXIFS(加電履歴!$B:$B,加電履歴!$F:$F,A2,加電履歴!$E:$E,"JAリスト")),"") | AQ2: =IFERROR(IF(COUNTIFS(加電履歴!$F:$F,A2,加電履歴!$E:$E,"JAリスト")=0,"",INDEX(加電履歴!$I:$I,MATCH(1,(加電履歴!$F:$F=A2)*(加電履歴!$E:$E="JAリスト")*(加電履歴!$B:$B=MAXIFS(加電履歴!$B:$B,加電履歴!$F:$F,A2,加電履歴!$E:$E,"JAリスト")),0))),"")
A3: JA北いしかり (旧JA北石狩) | B3: https://www.ja-kitaishikari.or.jp/ | C3: 北海道石狩郡当別町錦町53-57 (〒061-0295) ※本所は当別町 | D3: 0133-23-2530 | E3: にんじん、大根などの根菜類、稲作。 | F3: 収穫期における短期集中的な人員不足。選果場での労働者の高齢化。 | G3: 選果場での業務定着に向け、語学教育ノウハウを活かした入国前後の手厚い日本語支援をアピール。 | AG3: BREXA CrossBorder | AH3: 武田 悦郎 | AO3: =COUNTIFS(加電履歴!$F:$F,A3,加電履歴!$E:$E,"JAリスト") | AP3: =IFERROR(IF(COUNTIFS(加電履歴!$F:$F,A3,加電履歴!$E:$E,"JAリスト")=0,"",MAXIFS(加電履歴!$B:$B,加電履歴!$F:$F,A3,加電履歴!$E:$E,"JAリスト")),"") | AQ3: =IFERROR(IF(COUNTIFS(加電履歴!$F:$F,A3,加電履歴!$E:$E,"JAリスト")=0,"",INDEX(加電履歴!$I:$I,MATCH(1,(加電履歴!$F:$F=A3)*(加電履歴!$E:$E="JAリスト")*(加電履歴!$B:$B=MAXIFS(加電履歴!$B:$B,加電履歴!$F:$F,A3,加電履歴!$E:$E,"JAリスト")),0))),"")
A4: JA新しのつ | B4: https://www.ja-shinshinotsu.or.jp/ | C4: 北海道石狩郡新篠津村第47線北13 (〒068-1193) | D4: 0126-57-2311 | E4: クリーン農業を推進。米、玉ねぎ、白菜。 | F4: 村単位での労働力確保が難しく、外部からの人材流入が不可欠。 | G4: 村全体での受け入れ体制構築に向け、語学教育と人材紹介のハイブリッド支援を成果報酬で提案。 | AG4: BREXA CrossBorder | AH4: 武田 悦郎 | AO4: =COUNTIFS(加電履歴!$F:$F,A4,加電履歴!$E:$E,"JAリスト") | AP4: =IFERROR(IF(COUNTIFS(加電履歴!$F:$F,A4,加電履歴!$E:$E,"JAリスト")=0,"",MAXIFS(加電履歴!$B:$B,加電履歴!$F:$F,A4,加電履歴!$E:$E,"JAリスト")),"") | AQ4: =IFERROR(IF(COUNTIFS(加電履歴!$F:$F,A4,加電履歴!$E:$E,"JAリスト")=0,"",INDEX(加電履歴!$I:$I,MATCH(1,(加電履歴!$F:$F=A4)*(加電履歴!$E:$E="JAリスト")*(加電履歴!$B:$B=MAXIFS(加電履歴!$B:$B,加電履歴!$F:$F,A4,加電履歴!$E:$E,"JAリスト")),0))),"")
A5: JAいわみざわ | B5: https://ja-iwamizawa.or.jp/ | C5: 北海道岩見沢市2条西1丁目1番地 (〒068-0022) ※新本所 | D5: 0126-25-2211 | E5: 道内有数の稲作地帯。玉ねぎや小麦も大規模。 | F5: 大型機械オペレーターの補助や、玉ねぎの収穫・選別作業の人手不足。 | G5: 特定技能人材の提案とともに、初期費用ゼロの補助金活用スキームで導入ハードルを下げる。 | AG5: BREXA CrossBorder | AH5: 武田 悦郎 | AO5: =COUNTIFS(加電履歴!$F:$F,A5,加電履歴!$E:$E,"JAリスト") | AP5: =IFERROR(IF(COUNTIFS(加電履歴!$F:$F,A5,加電履歴!$E:$E,"JAリスト")=0,"",MAXIFS(加電履歴!$B:$B,加電履歴!$F:$F,A5,加電履歴!$E:$E,"JAリスト")),"") | AQ5: =IFERROR(IF(COUNTIFS(加電履歴!$F:$F,A5,加電履歴!$E:$E,"JAリスト")=0,"",INDEX(加電履歴!$I:$I,MATCH(1,(加電履歴!$F:$F=A5)*(加電履歴!$E:$E="JAリスト")*(加電履歴!$B:$B=MAXIFS(加電履歴!$B:$B,加電履歴!$F:$F,A5,加電履歴!$E:$E,"JAリスト")),0))),"")
A6: JAみねのぶ | B6: http://www.ja-minenobu.or.jp/ | C6: 北海道美唄市峰延町本町1862-1 | D6: 0126-67-2111 | E6: 米、メロン、アスパラなどの高付加価値作物。 | F6: 手作業が必要な収穫作業において、繊細な作業ができる人材が求められる。 | G6: やさしい日本語講座を通じた細やかなコミュニケーション支援を強調し、作業ミスの防止をアピール。 | AG6: BREXA CrossBorder | AH6: 武田 悦郎 | AO6: =COUNTIFS(加電履歴!$F:$F,A6,加電履歴!$E:$E,"JAリスト") | AP6: =IFERROR(IF(COUNTIFS(加電履歴!$F:$F,A6,加電履歴!$E:$E,"JAリスト")=0,"",MAXIFS(加電履歴!$B:$B,加電履歴!$F:$F,A6,加電履歴!$E:$E,"JAリスト")),"") | AQ6: =IFERROR(IF(COUNTIFS(加電履歴!$F:$F,A6,加電履歴!$E:$E,"JAリスト")=0,"",INDEX(加電履歴!$I:$I,MATCH(1,(加電履歴!$F:$F=A6)*(加電履歴!$E:$E="JAリスト")*(加電履歴!$B:$B=MAXIFS(加電履歴!$B:$B,加電履歴!$F:$F,A6,加電履歴!$E:$E,"JAリスト")),0))),"")
A7: JAびばい | B7: https://www.ja-bibai.or.jp/ | C7: 北海道美唄市大通東1条北1-2-1 | D7: 0126-63-2162 | E7: 米、グリーンアスパラ、雪中キャベツ。 | F7: 冬季の特産品もあり、年間を通した労働力の確保が課題。 | G7: 通年雇用を前提とした人材配置。補助金活用によるコスト削減効果をシミュレーションして提示。 | AG7: BREXA CrossBorder | AH7: 武田 悦郎 | AO7: =COUNTIFS(加電履歴!$F:$F,A7,加電履歴!$E:$E,"JAリスト") | AP7: =IFERROR(IF(COUNTIFS(加電履歴!$F:$F,A7,加電履歴!$E:$E,"JAリスト")=0,"",MAXIFS(加電履歴!$B:$B,加電履歴!$F:$F,A7,加電履歴!$E:$E,"JAリスト")),"") | AQ7: =IFERROR(IF(COUNTIFS(加電履歴!$F:$F,A7,加電履歴!$E:$E,"JAリスト")=0,"",INDEX(加電履歴!$I:$I,MATCH(1,(加電履歴!$F:$F=A7)*(加電履歴!$E:$E="JAリスト")*(加電履歴!$B:$B=MAXIFS(加電履歴!$B:$B,加電履歴!$F:$F,A7,加電履歴!$E:$E,"JAリスト")),0))),"")
A8: JAたきかわ | B8: https://www.ja-takikawa.com/ | C8: 北海道滝川市本町4丁目1-31 | D8: 0125-22-3401 | E8: りんご、米、菜の花、小麦、玉ねぎ。 | F8: 果樹の剪定や収穫など、技術習得が必要な作業が多い。 | G8: 長期就労を見据えた技能実習からの移行支援と、継続的な語学・生活サポートを提案。 | AG8: BREXA CrossBorder | AH8: 武田 悦郎 | AO8: =COUNTIFS(加電履歴!$F:$F,A8,加電履歴!$E:$E,"JAリスト") | AP8: =IFERROR(IF(COUNTIFS(加電履歴!$F:$F,A8,加電履歴!$E:$E,"JAリスト")=0,"",MAXIFS(加電履歴!$B:$B,加電履歴!$F:$F,A8,加電履歴!$E:$E,"JAリスト")),"") | AQ8: =IFERROR(IF(COUNTIFS(加電履歴!$F:$F,A8,加電履歴!$E:$E,"JAリスト")=0,"",INDEX(加電履歴!$I:$I,MATCH(1,(加電履歴!$F:$F=A8)*(加電履歴!$E:$E="JAリスト")*(加電履歴!$B:$B=MAXIFS(加電履歴!$B:$B,加電履歴!$F:$F,A8,加電履歴!$E:$E,"JAリスト")),0))),"")
A9: JA新すながわ | B9: https://jashinsunagawa.or.jp/ | C9: 北海道砂川市東1条南1-1-20 | D9: 0125-54-3181 | E9: ゆめぴりか等の高品質米、トマト。 | F9: ハウス栽培における温度管理や収穫作業の労働力不足。 | G9: リスクのない完全成果報酬型モデルを強調し、初めての外国人材受け入れテスト導入を打診。 | AG9: BREXA CrossBorder | AH9: 武田 悦郎 | AO9: =COUNTIFS(加電履歴!$F:$F,A9,加電履歴!$E:$E,"JAリスト") | AP9: =IFERROR(IF(COUNTIFS(加電履歴!$F:$F,A9,加電履歴!$E:$E,"JAリスト")=0,"",MAXIFS(加電履歴!$B:$B,加電履歴!$F:$F,A9,加電履歴!$E:$E,"JAリスト")),"") | AQ9: =IFERROR(IF(COUNTIFS(加電履歴!$F:$F,A9,加電履歴!$E:$E,"JAリスト")=0,"",INDEX(加電履歴!$I:$I,MATCH(1,(加電履歴!$F:$F=A9)*(加電履歴!$E:$E="JAリスト")*(加電履歴!$B:$B=MAXIFS(加電履歴!$B:$B,加電履歴!$F:$F,A9,加電履歴!$E:$E,"JAリスト")),0))),"")
A10: JA月形町 | B10: https://www.hamanasu.to/ja-moon/ | C10: 北海道樺戸郡月形町1069番地 | D10: 0126-53-2111 | E10: 花き（切り花）、メロン、スイカ、トマト。 | F10: 花き栽培は手作業が多く、繁忙期の労働力確保が死活問題。 | G10: 繊細な作業指示が伝わるよう、独自の語学教育プログラム（異文化理解・日本語講座）を強みとする。 | AG10: BREXA CrossBorder | AH10: 武田 悦郎 | AO10: =COUNTIFS(加電履歴!$F:$F,A10,加電履歴!$E:$E,"JAリスト") | AP10: =IFERROR(IF(COUNTIFS(加電履歴!$F:$F,A10,加電履歴!$E:$E,"JAリスト")=0,"",MAXIFS(加電履歴!$B:$B,加電履歴!$F:$F,A10,加電履歴!$E:$E,"JAリスト")),"") | AQ10: =IFERROR(IF(COUNTIFS(加電履歴!$F:$F,A10,加電履歴!$E:$E,"JAリスト")=0,"",INDEX(加電履歴!$I:$I,MATCH(1,(加電履歴!$F:$F=A10)*(加電履歴!$E:$E="JAリスト")*(加電履歴!$B:$B=MAXIFS(加電履歴!$B:$B,加電履歴!$F:$F,A10,加電履歴!$E:$E,"JAリスト")),0))),"")
A11: JAきたそらち | B11: https://www.ja-kitasorachi.com/ | C11: 北海道深川市深川町字メム10号線山3線5850番地 (〒074-0015) | D11: 0164-22-6600 | E11: 米、そば、りんご、メロン。 | F11: そばや米の大規模栽培における収穫補助、選果場での人材不足。 | G11: 補助金申請サポートを含む一気通貫の支援体制を提示し、組合員（農家）への直接紹介を仰ぐ。 | AG11: BREXA CrossBorder | AH11: 武田 悦郎 | AO11: =COUNTIFS(加電履歴!$F:$F,A11,加電履歴!$E:$E,"JAリスト") | AP11: =IFERROR(IF(COUNTIFS(加電履歴!$F:$F,A11,加電履歴!$E:$E,"JAリスト")=0,"",MAXIFS(加電履歴!$B:$B,加電履歴!$F:$F,A11,加電履歴!$E:$E,"JAリスト")),"") | AQ11: =IFERROR(IF(COUNTIFS(加電履歴!$F:$F,A11,加電履歴!$E:$E,"JAリスト")=0,"",INDEX(加電履歴!$I:$I,MATCH(1,(加電履歴!$F:$F=A11)*(加電履歴!$E:$E="JAリスト")*(加電履歴!$B:$B=MAXIFS(加電履歴!$B:$B,加電履歴!$F:$F,A11,加電履歴!$E:$E,"JAリスト")),0))),"")
A12: JA北いぶき | B12: https://www.ja-kitaibuki.or.jp/ | C12: 北海道雨竜郡秩父別町1298-8 (〒078-2102) ※本所・秩父別支所 | D12: 0164-33-2011 | E12: トマト、ブロッコリー、米。 | F12: 鮮度が命の作物において、収穫タイミングを逃さないための人員確保。 | G12: 語学教育の知見を活かした「現場で使える日本語」の事前教育を強調し、即戦力化をアピール。 | AG12: BREXA CrossBorder | AH12: 武田 悦郎 | AO12: =COUNTIFS(加電履歴!$F:$F,A12,加電履歴!$E:$E,"JAリスト") | AP12: =IFERROR(IF(COUNTIFS(加電履歴!$F:$F,A12,加電履歴!$E:$E,"JAリスト")=0,"",MAXIFS(加電履歴!$B:$B,加電履歴!$F:$F,A12,加電履歴!$E:$E,"JAリスト")),"") | AQ12: =IFERROR(IF(COUNTIFS(加電履歴!$F:$F,A12,加電履歴!$E:$E,"JAリスト")=0,"",INDEX(加電履歴!$I:$I,MATCH(1,(加電履歴!$F:$F=A12)*(加電履歴!$E:$E="JAリスト")*(加電履歴!$B:$B=MAXIFS(加電履歴!$B:$B,加電履歴!$F:$F,A12,加電履歴!$E:$E,"JAリスト")),0))),"")
A13: JAピンネ | B13: https://www.japinne.or.jp/ | C13: 北海道樺戸郡新十津川町字中央6番地29 (〒073-1103) | D13: 0125-76-2221 | E13: 米、メロン、アスパラガス。 | F13: 農業従事者の高齢化が顕著であり、若手労働力の確保が急務。 | G13: 初期費用の持ち出しがないスキームを説明し、若手特定技能人材による事業継承サポートを提案。 | AG13: BREXA CrossBorder | AH13: 武田 悦郎 | AO13: =COUNTIFS(加電履歴!$F:$F,A13,加電履歴!$E:$E,"JAリスト") | AP13: =IFERROR(IF(COUNTIFS(加電履歴!$F:$F,A13,加電履歴!$E:$E,"JAリスト")=0,"",MAXIFS(加電履歴!$B:$B,加電履歴!$F:$F,A13,加電履歴!$E:$E,"JAリスト")),"") | AQ13: =IFERROR(IF(COUNTIFS(加電履歴!$F:$F,A13,加電履歴!$E:$E,"JAリスト")=0,"",INDEX(加電履歴!$I:$I,MATCH(1,(加電履歴!$F:$F=A13)*(加電履歴!$E:$E="JAリスト")*(加電履歴!$B:$B=MAXIFS(加電履歴!$B:$B,加電履歴!$F:$F,A13,加電履歴!$E:$E,"JAリスト")),0))),"")
... A22: JAぴっぷ町 | B22: https://www.ja-pippu.or.jp/ | C22: 北海道上川郡比布町西町3-5-14 | D22: 0166-85-2121 ※公式サイトで再確認推奨 | E22: いちご、米、千本ねぎ。 | F22: いちご収穫など、腰をかがめる手作業が多く若手人材が急務。 | G22: 補助金採択を前提とした完全成果報酬を提示し、まずは小規模な農家からのテスト受け入れを打診。 | AG22: BREXA CrossBorder | AH22: 武田 悦郎 | AO22: =COUNTIFS(加電履歴!$F:$F,A22,加電履歴!$E:$E,"JAリスト") | AP22: =IFERROR(IF(COUNTIFS(加電履歴!$F:$F,A22,加電履歴!$E:$E,"JAリスト")=0,"",MAXIFS(加電履歴!$B:$B,加電履歴!$F:$F,A22,加電履歴!$E:$E,"JAリスト")),"") | AQ22: =IFERROR(IF(COUNTIFS(加電履歴!$F:$F,A22,加電履歴!$E:$E,"JAリスト")=0,"",INDEX(加電履歴!$I:$I,MATCH(1,(加電履歴!$F:$F=A22)*(加電履歴!$E:$E="JAリスト")*(加電履歴!$B:$B=MAXIFS(加電履歴!$B:$B,加電履歴!$F:$F,A22,加電履歴!$E:$E,"JAリスト")),0))),"")
A23: JA北ひびき | C23: 士別市 | D23: 0165-23-2179 | E23: アスパラガス、メロン、ビート、小麦。 | F23: 作付面積の拡大に伴い、機械操作補助や収穫・運搬の担い手が不足。 | G23: 語学教育と人材紹介のセット提案により、機械操作の安全指導がスムーズに行える点をアピール。 | AG23: BREXA CrossBorder | AH23: 武田 悦郎 | AO23: =COUNTIFS(加電履歴!$F:$F,A23,加電履歴!$E:$E,"JAリスト") | AP23: =IFERROR(IF(COUNTIFS(加電履歴!$F:$F,A23,加電履歴!$E:$E,"JAリスト")=0,"",MAXIFS(加電履歴!$B:$B,加電履歴!$F:$F,A23,加電履歴!$E:$E,"JAリスト")),"") | AQ23: =IFERROR(IF(COUNTIFS(加電履歴!$F:$F,A23,加電履歴!$E:$E,"JAリスト")=0,"",INDEX(加電履歴!$I:$I,MATCH(1,(加電履歴!$F:$F=A23)*(加電履歴!$E:$E="JAリスト")*(加電履歴!$B:$B=MAXIFS(加電履歴!$B:$B,加電履歴!$F:$F,A23,加電履歴!$E:$E,"JAリスト")),0))),"")
A24: JA道北なよろ (旧JA名寄) | B24: https://www.ja-douhokunayoro.or.jp/ | C24: 北海道名寄市大通南4丁目10番地1 ※本所 | D24: 01654-2-4531 | E24: もち米（作付面積日本一）、アスパラ。 | F24: オペレーター補助や、アスパラの早朝収穫の担い手不足。 | G24: 朝早くからの作業にも対応できる人材紹介と、手厚いメンタル・生活サポート体制を強調。 | AG24: BREXA CrossBorder | AH24: 武田 悦郎 | AO24: =COUNTIFS(加電履歴!$F:$F,A24,加電履歴!$E:$E,"JAリスト") | AP24: =IFERROR(IF(COUNTIFS(加電履歴!$F:$F,A24,加電履歴!$E:$E,"JAリスト")=0,"",MAXIFS(加電履歴!$B:$B,加電履歴!$F:$F,A24,加電履歴!$E:$E,"JAリスト")),"") | AQ24: =IFERROR(IF(COUNTIFS(加電履歴!$F:$F,A24,加電履歴!$E:$E,"JAリスト")=0,"",INDEX(加電履歴!$I:$I,MATCH(1,(加電履歴!$F:$F=A24)*(加電履歴!$E:$E="JAリスト")*(加電履歴!$B:$B=MAXIFS(加電履歴!$B:$B,加電履歴!$F:$F,A24,加電履歴!$E:$E,"JAリスト")),0))),"")
A25: JA南るもい ※令和3年JAるもいへ合併・現存せず | C25: ※統合: JAるもい本所(羽幌町)。連絡先はJAるもい(0164-62-1212系) ※要確認 | D25: ※存続: JAるもい | E25: 米、メロン、カボチャ。 | F25: 気候を活かした農業だが、過疎化により働き手の絶対数が不足。 | G25: 補助金活用により採用コストを圧縮し、過疎地域でも定着を図れるフォロー体制（語学支援等）を提案。 | AG25: BREXA CrossBorder | AH25: 武田 悦郎 | AO25: =COUNTIFS(加電履歴!$F:$F,A25,加電履歴!$E:$E,"JAリスト") | AP25: =IFERROR(IF(COUNTIFS(加電履歴!$F:$F,A25,加電履歴!$E:$E,"JAリスト")=0,"",MAXIFS(加電履歴!$B:$B,加電履歴!$F:$F,A25,加電履歴!$E:$E,"JAリスト")),"") | AQ25: =IFERROR(IF(COUNTIFS(加電履歴!$F:$F,A25,加電履歴!$E:$E,"JAリスト")=0,"",INDEX(加電履歴!$I:$I,MATCH(1,(加電履歴!$F:$F=A25)*(加電履歴!$E:$E="JAリスト")*(加電履歴!$B:$B=MAXIFS(加電履歴!$B:$B,加電履歴!$F:$F,A25,加電履歴!$E:$E,"JAリスト")),0))),"")
A26: JAオロロン ※令和3年JAるもいへ合併・現存せず | C26: ※統合: JAるもい本所(羽幌町)。羽幌町字南町7-29(JAるもい本所と同位置の可能性) | D26: ※存続: JAるもい | E26: 米、アスパラガス、オロロンメロン。 | F26: 沿岸部であり、水産業との複合的な労働力確保のニーズも存在。 | G26: 農業だけでなく、地域のニーズに合わせて柔軟に特定技能（飲食料品製造等）の提案枠を広げる。 | AG26: BREXA CrossBorder | AH26: 武田 悦郎 | AO26: =COUNTIFS(加電履歴!$F:$F,A26,加電履歴!$E:$E,"JAリスト") | AP26: =IFERROR(IF(COUNTIFS(加電履歴!$F:$F,A26,加電履歴!$E:$E,"JAリスト")=0,"",MAXIFS(加電履歴!$B:$B,加電履歴!$F:$F,A26,加電履歴!$E:$E,"JAリスト")),"") | AQ26: =IFERROR(IF(COUNTIFS(加電履歴!$F:$F,A26,加電履歴!$E:$E,"JAリスト")=0,"",INDEX(加電履歴!$I:$I,MATCH(1,(加電履歴!$F:$F=A26)*(加電履歴!$E:$E="JAリスト")*(加電履歴!$B:$B=MAXIFS(加電履歴!$B:$B,加電履歴!$F:$F,A26,加電履歴!$E:$E,"JAリスト")),0))),"")
A27: JA北宗谷 | B27: https://ja-kitasouya.jp/ | C27: 北海道天塩郡豊富町 | D27: 0162-82-2112 | E27: 広大な牧草地での大規模酪農。 | F27: 年中無休の搾乳作業や清掃など、特有の過酷な労働環境による人手不足。 | G27: 酪農特化の特定技能紹介と、初期投資ゼロ（完全成果報酬）による経営圧迫の回避を提案。 | AG27: BREXA CrossBorder | AH27: 武田 悦郎 | AO27: =COUNTIFS(加電履歴!$F:$F,A27,加電履歴!$E:$E,"JAリスト") | AP27: =IFERROR(IF(COUNTIFS(加電履歴!$F:$F,A27,加電履歴!$E:$E,"JAリスト")=0,"",MAXIFS(加電履歴!$B:$B,加電履歴!$F:$F,A27,加電履歴!$E:$E,"JAリスト")),"") | AQ27: =IFERROR(IF(COUNTIFS(加電履歴!$F:$F,A27,加電履歴!$E:$E,"JAリスト")=0,"",INDEX(加電履歴!$I:$I,MATCH(1,(加電履歴!$F:$F=A27)*(加電履歴!$E:$E="JAリスト")*(加電履歴!$B:$B=MAXIFS(加電履歴!$B:$B,加電履歴!$F:$F,A27,加電履歴!$E:$E,"JAリスト")),0))),"")
A28: JA宗谷南 | B28: http://ja-souyaminami.or.jp/ | C28: 北海道枝幸郡枝幸町幸町8121-3 (〒098-5805) | D28: 0163-62-1711 | E28: 酪農、肉牛飼育。 | F28: 冬季の厳しい気象条件の中での作業となるため、人材のケアが最大の課題。 | G28: 入国前のオリエンテーション（雪国での生活指導）や、定期的な日本語でのメンタルケアをアピール。 | AG28: BREXA CrossBorder | AH28: 武田 悦郎 | AO28: =COUNTIFS(加電履歴!$F:$F,A28,加電履歴!$E:$E,"JAリスト") | AP28: =IFERROR(IF(COUNTIFS(加電履歴!$F:$F,A28,加電履歴!$E:$E,"JAリスト")=0,"",MAXIFS(加電履歴!$B:$B,加電履歴!$F:$F,A28,加電履歴!$E:$E,"JAリスト")),"") | AQ28: =IFERROR(IF(COUNTIFS(加電履歴!$F:$F,A28,加電履歴!$E:$E,"JAリスト")=0,"",INDEX(加電履歴!$I:$I,MATCH(1,(加電履歴!$F:$F=A28)*(加電履歴!$E:$E="JAリスト")*(加電履歴!$B:$B=MAXIFS(加電履歴!$B:$B,加電履歴!$F:$F,A28,加電履歴!$E:$E,"JAリスト")),0))),"")
A29: JAひがし宗谷 (東宗谷農業協同組合) | B29: https://www.ja-esoya.com/ | C29: 北海道枝幸郡浜頓別町南3条1丁目25番地 | D29: 01634-2-2229 (本所) / 01634-2-3366 (金融部) | E29: 酪農中心。 | F29: ヘルパー不足が深刻で、酪農家が休みを取れない状況が続いている。 | G29: 労働環境を改善するため、補助金を活用した外国人材の計画的な受け入れスキームを提案。 | AG29: BREXA CrossBorder | AH29: 武田 悦郎 | AO29: =COUNTIFS(加電履歴!$F:$F,A29,加電履歴!$E:$E,"JAリスト") | AP29: =IFERROR(IF(COUNTIFS(加電履歴!$F:$F,A29,加電履歴!$E:$E,"JAリスト")=0,"",MAXIFS(加電履歴!$B:$B,加電履歴!$F:$F,A29,加電履歴!$E:$E,"JAリスト")),"") | AQ29: =IFERROR(IF(COUNTIFS(加電履歴!$F:$F,A29,加電履歴!$E:$E,"JAリスト")=0,"",INDEX(加電履歴!$I:$I,MATCH(1,(加電履歴!$F:$F=A29)*(加電履歴!$E:$E="JAリスト")*(加電履歴!$B:$B=MAXIFS(加電履歴!$B:$B,加電履歴!$F:$F,A29,加電履歴!$E:$E,"JAリスト")),0))),"")
A30: JAきたみらい | B30: https://www.jakitamirai.or.jp/ | C30: 北海道北見市中ノ島町1丁目1-8 (〒090-0813) | D30: 0157-32-8777 | E30: 玉ねぎ（日本一）、じゃがいも、てんさい。 | F30: 玉ねぎ収穫・選別施設における膨大な労働力確保。ピーク時の不足が深刻。 | G30: 大規模選果場向けのまとまった人材紹介と、現場リーダー候補に対する日本語教育支援をセット提案。 | AG30: BREXA CrossBorder | AH30: 武田 悦郎 | AO30: =COUNTIFS(加電履歴!$F:$F,A30,加電履歴!$E:$E,"JAリスト") | AP30: =IFERROR(IF(COUNTIFS(加電履歴!$F:$F,A30,加電履歴!$E:$E,"JAリスト")=0,"",MAXIFS(加電履歴!$B:$B,加電履歴!$F:$F,A30,加電履歴!$E:$E,"JAリスト")),"") | AQ30: =IFERROR(IF(COUNTIFS(加電履歴!$F:$F,A30,加電履歴!$E:$E,"JAリスト")=0,"",INDEX(加電履歴!$I:$I,MATCH(1,(加電履歴!$F:$F=A30)*(加電履歴!$E:$E="JAリスト")*(加電履歴!$B:$B=MAXIFS(加電履歴!$B:$B,加電履歴!$F:$F,A30,加電履歴!$E:$E,"JAリスト")),0))),"")
A31: JAところ | B31: https://www.ja-tokoro.or.jp/ | C31: 北海道北見市常呂町字常呂608 (〒093-0206) | D31: 0152-54-2121 | E31: 玉ねぎ、にんにく、小麦。 | F31: にんにくや玉ねぎの植え付け・収穫における短期集中的な労働需要。 | G31: 完全成果報酬型モデルを提示し、コストリスクなしで繁忙期に向けた人員確保の準備を促す。 | AG31: BREXA CrossBorder | AH31: 武田 悦郎 | AO31: =COUNTIFS(加電履歴!$F:$F,A31,加電履歴!$E:$E,"JAリスト") | AP31: =IFERROR(IF(COUNTIFS(加電履歴!$F:$F,A31,加電履歴!$E:$E,"JAリスト")=0,"",MAXIFS(加電履歴!$B:$B,加電履歴!$F:$F,A31,加電履歴!$E:$E,"JAリスト")),"") | AQ31: =IFERROR(IF(COUNTIFS(加電履歴!$F:$F,A31,加電履歴!$E:$E,"JAリスト")=0,"",INDEX(加電履歴!$I:$I,MATCH(1,(加電履歴!$F:$F=A31)*(加電履歴!$E:$E="JAリスト")*(加電履歴!$B:$B=MAXIFS(加電履歴!$B:$B,加電履歴!$F:$F,A31,加電履歴!$E:$E,"JAリスト")),0))),"")
A32: JAめまんべつ | B32: https://www.ja-memanbetsu.jp/ | C32: 北海道網走郡大空町女満別西4条5丁目1-27 (〒099-2324) | D32: 0152-74-2131 | E32: 麦、ビート、じゃがいも、長いも。 | F32: 長いもの収穫など重労働が多く、体力のある若手人材の確保が必須。 | G32: 生活サポートや日本語教育を通じて、若手人材が地域社会に馴染みやすくする独自の支援体制をアピール。 | AG32: BREXA CrossBorder | AH32: 武田 悦郎 | AO32: =COUNTIFS(加電履歴!$F:$F,A32,加電履歴!$E:$E,"JAリスト") | AP32: =IFERROR(IF(COUNTIFS(加電履歴!$F:$F,A32,加電履歴!$E:$E,"JAリスト")=0,"",MAXIFS(加電履歴!$B:$B,加電履歴!$F:$F,A32,加電履歴!$E:$E,"JAリスト")),"") | AQ32: =IFERROR(IF(COUNTIFS(加電履歴!$F:$F,A32,加電履歴!$E:$E,"JAリスト")=0,"",INDEX(加電履歴!$I:$I,MATCH(1,(加電履歴!$F:$F=A32)*(加電履歴!$E:$E="JAリスト")*(加電履歴!$B:$B=MAXIFS(加電履歴!$B:$B,加電履歴!$F:$F,A32,加電履歴!$E:$E,"JAリスト")),0))),"")
A33: JAびほろ | B33: https://www.ja-bihoro.or.jp/ | C33: 北海道網走郡美幌町字青山南30番地1 (〒092-8651) | D33: 0152-72-1111 | E33: 玉ねぎ、じゃがいも、ビート。 | F33: 大規模機械化が進むが、機械で代替できない選別作業等の人手が必要。 | G33: 指示の理解度を高めるための「やさしい日本語講座」を提供し、作業効率の低下を防ぐ支援を強調。 | AG33: BREXA CrossBorder | AH33: 武田 悦郎 | AO33: =COUNTIFS(加電履歴!$F:$F,A33,加電履歴!$E:$E,"JAリスト") | AP33: =IFERROR(IF(COUNTIFS(加電履歴!$F:$F,A33,加電履歴!$E:$E,"JAリスト")=0,"",MAXIFS(加電履歴!$B:$B,加電履歴!$F:$F,A33,加電履歴!$E:$E,"JAリスト")),"") | AQ33: =IFERROR(IF(COUNTIFS(加電履歴!$F:$F,A33,加電履歴!$E:$E,"JAリスト")=0,"",INDEX(加電履歴!$I:$I,MATCH(1,(加電履歴!$F:$F=A33)*(加電履歴!$E:$E="JAリスト")*(加電履歴!$B:$B=MAXIFS(加電履歴!$B:$B,加電履歴!$F:$F,A33,加電履歴!$E:$E,"JAリスト")),0))),"")
A34: JAつべつ | B34: https://www.jatsubetsu.or.jp/ | C34: 北海道網走郡津別町字大通30番地1 (〒092-0231) | D34: 0152-76-3322 | E34: アスパラガス、じゃがいも、酪農。 | F34: 畑作と酪農が混在し、農家によって求める人材のスキルセットが異なる。 | G34: 人材紹介の専門性を活かした緻密なマッチングと、補助金申請サポートによる安心感を提供。 | AG34: BREXA CrossBorder | AH34: 武田 悦郎 | AO34: =COUNTIFS(加電履歴!$F:$F,A34,加電履歴!$E:$E,"JAリスト") | AP34: =IFERROR(IF(COUNTIFS(加電履歴!$F:$F,A34,加電履歴!$E:$E,"JAリスト")=0,"",MAXIFS(加電履歴!$B:$B,加電履歴!$F:$F,A34,加電履歴!$E:$E,"JAリスト")),"") | AQ34: =IFERROR(IF(COUNTIFS(加電履歴!$F:$F,A34,加電履歴!$E:$E,"JAリスト")=0,"",INDEX(加電履歴!$I:$I,MATCH(1,(加電履歴!$F:$F=A34)*(加電履歴!$E:$E="JAリスト")*(加電履歴!$B:$B=MAXIFS(加電履歴!$B:$B,加電履歴!$F:$F,A34,加電履歴!$E:$E,"JAリスト")),0))),"")
A35: JAしれとこ斜里 (旧JA斜里町) | B35: https://ja-shiretokoshari.or.jp/ | C35: 北海道斜里郡斜里町本町36-1 (〒099-4195) | D35: 0152-23-3151 | E35: じゃがいも、てんさい、にんじん。 | F35: 知床の厳しい自然環境下での大規模農業。収穫期の選果場労働力がボトルネック。 | G35: 手厚い生活指導と語学サポートにより、地方の環境でも孤立させない定着支援プログラムを提案。 | AG35: BREXA CrossBorder | AH35: 武田 悦郎 | AO35: =COUNTIFS(加電履歴!$F:$F,A35,加電履歴!$E:$E,"JAリスト") | AP35: =IFERROR(IF(COUNTIFS(加電履歴!$F:$F,A35,加電履歴!$E:$E,"JAリスト")=0,"",MAXIFS(加電履歴!$B:$B,加電履歴!$F:$F,A35,加電履歴!$E:$E,"JAリスト")),"") | AQ35: =IFERROR(IF(COUNTIFS(加電履歴!$F:$F,A35,加電履歴!$E:$E,"JAリスト")=0,"",INDEX(加電履歴!$I:$I,MATCH(1,(加電履歴!$F:$F=A35)*(加電履歴!$E:$E="JAリスト")*(加電履歴!$B:$B=MAXIFS(加電履歴!$B:$B,加電履歴!$F:$F,A35,加電履歴!$E:$E,"JAリスト")),0))),"")
A36: JA清里町 | B36: https://ja-kiyosato.or.jp/ | C36: 北海道斜里郡清里町羽衣町2 (〒099-4405) | D36: 0152-25-2212 | E36: じゃがいも（焼酎原料含む）、小麦。 | F36: 焼酎工場などの加工施設連携もあり、農作業以外の関連業務への波及効果も。 | G36: 補助金採択を前提とした完全成果報酬で、組合を通じた地域全体の労働力底上げを打診する。 | AG36: BREXA CrossBorder | AH36: 武田 悦郎 | AO36: =COUNTIFS(加電履歴!$F:$F,A36,加電履歴!$E:$E,"JAリスト") | AP36: =IFERROR(IF(COUNTIFS(加電履歴!$F:$F,A36,加電履歴!$E:$E,"JAリスト")=0,"",MAXIFS(加電履歴!$B:$B,加電履歴!$F:$F,A36,加電履歴!$E:$E,"JAリスト")),"") | AQ36: =IFERROR(IF(COUNTIFS(加電履歴!$F:$F,A36,加電履歴!$E:$E,"JAリスト")=0,"",INDEX(加電履歴!$I:$I,MATCH(1,(加電履歴!$F:$F=A36)*(加電履歴!$E:$E="JAリスト")*(加電履歴!$B:$B=MAXIFS(加電履歴!$B:$B,加電履歴!$F:$F,A36,加電履歴!$E:$E,"JAリスト")),0))),"")
A37: JAこしみず | B37: https://ja-koshimizu.jp/ | C37: 北海道斜里郡小清水町南町1-5-27 | D37: 0152-62-2111 | E37: じゃがいも、小麦、てんさい。 | F37: 大規模畑作地帯におけるトラクターオペレーター不足と収穫補助員の人材難。 | G37: 安全な作業を実現するための語学・コミュニケーション教育の専門性を、他社にはない強みとしてアピール。 | AG37: BREXA CrossBorder | AH37: 武田 悦郎 | AO37: =COUNTIFS(加電履歴!$F:$F,A37,加電履歴!$E:$E,"JAリスト") | AP37: =IFERROR(IF(COUNTIFS(加電履歴!$F:$F,A37,加電履歴!$E:$E,"JAリスト")=0,"",MAXIFS(加電履歴!$B:$B,加電履歴!$F:$F,A37,加電履歴!$E:$E,"JAリスト")),"") | AQ37: =IFERROR(IF(COUNTIFS(加電履歴!$F:$F,A37,加電履歴!$E:$E,"JAリスト")=0,"",INDEX(加電履歴!$I:$I,MATCH(1,(加電履歴!$F:$F=A37)*(加電履歴!$E:$E="JAリスト")*(加電履歴!$B:$B=MAXIFS(加電履歴!$B:$B,加電履歴!$F:$F,A37,加電履歴!$E:$E,"JAリスト")),0))),"")
A38: JAえんゆう | B38: https://www.ja-enyu.com/ | C38: 北海道紋別郡湧別町上湧別屯田市街地230番地 (〒099-6501) ※本所 | D38: 01586-2-2161 | E38: 玉ねぎ、アスパラガス、酪農。 | F38: 広域合併による大規模JAであり、管内での労働力の偏りや一括した採用管理が課題。 | G38: JA本所を一括窓口とした、補助金申請から日本語教育、定着支援までをパッケージ化した総合提案。 | AG38: BREXA CrossBorder | AH38: 武田 悦郎 | AO38: =COUNTIFS(加電履歴!$F:$F,A38,加電履歴!$E:$E,"JAリスト") | AP38: =IFERROR(IF(COUNTIFS(加電履歴!$F:$F,A38,加電履歴!$E:$E,"JAリスト")=0,"",MAXIFS(加電履歴!$B:$B,加電履歴!$F:$F,A38,加電履歴!$E:$E,"JAリスト")),"") | AQ38: =IFERROR(IF(COUNTIFS(加電履歴!$F:$F,A38,加電履歴!$E:$E,"JAリスト")=0,"",INDEX(加電履歴!$I:$I,MATCH(1,(加電履歴!$F:$F=A38)*(加電履歴!$E:$E="JAリスト")*(加電履歴!$B:$B=MAXIFS(加電履歴!$B:$B,加電履歴!$F:$F,A38,加電履歴!$E:$E,"JAリスト")),0))),"")
A39: JA帯広かわにし | B39: https://www.jaobihirokawanisi.or.jp/ | C39: 北海道帯広市川西町西2線61番地の1 (〒089-1198) | D39: 0155-59-2111 | E39: 長いも（台湾等へ輸出）、じゃがいも。 | F39: 輸出向け長いもの徹底した品質管理と、選果場での大規模な人員確保。 | G39: グローバルな視点を持つJAに対し、異文化理解や語学に強い人材紹介スキームを提案。 | AG39: BREXA CrossBorder | AH39: 武田 悦郎 | AO39: =COUNTIFS(加電履歴!$F:$F,A39,加電履歴!$E:$E,"JAリスト") | AP39: =IFERROR(IF(COUNTIFS(加電履歴!$F:$F,A39,加電履歴!$E:$E,"JAリスト")=0,"",MAXIFS(加電履歴!$B:$B,加電履歴!$F:$F,A39,加電履歴!$E:$E,"JAリスト")),"") | AQ39: =IFERROR(IF(COUNTIFS(加電履歴!$F:$F,A39,加電履歴!$E:$E,"JAリスト")=0,"",INDEX(加電履歴!$I:$I,MATCH(1,(加電履歴!$F:$F=A39)*(加電履歴!$E:$E="JAリスト")*(加電履歴!$B:$B=MAXIFS(加電履歴!$B:$B,加電履歴!$F:$F,A39,加電履歴!$E:$E,"JAリスト")),0))),"")
A40: JAおびひろ ※2003年JA帯広かわにしへ合併・現存せず | C40: ※旧帯広市農協はJA帯広かわにしに統合済み (Row 39参照) | D40: ※存続団体: JA帯広かわにし 0155-59-2111 | E40: 畑作全般、酪農。 | F40: 都市部と隣接する農業エリアでの、多様な労働力ニーズの混在。 | G40: 成果報酬型で導入リスクを排除しつつ、語学教育の知見を応用した独自の日本語サポートを提示。 | AG40: BREXA CrossBorder | AH40: 武田 悦郎 | AO40: =COUNTIFS(加電履歴!$F:$F,A40,加電履歴!$E:$E,"JAリスト") | AP40: =IFERROR(IF(COUNTIFS(加電履歴!$F:$F,A40,加電履歴!$E:$E,"JAリスト")=0,"",MAXIFS(加電履歴!$B:$B,加電履歴!$F:$F,A40,加電履歴!$E:$E,"JAリスト")),"") | AQ40: =IFERROR(IF(COUNTIFS(加電履歴!$F:$F,A40,加電履歴!$E:$E,"JAリスト")=0,"",INDEX(加電履歴!$I:$I,MATCH(1,(加電履歴!$F:$F=A40)*(加電履歴!$E:$E="JAリスト")*(加電履歴!$B:$B=MAXIFS(加電履歴!$B:$B,加電履歴!$F:$F,A40,加電履歴!$E:$E,"JAリスト")),0))),"")
A41: JAおとふけ | B41: https://www.ja-otofuke.jp/ | C41: 北海道河東郡音更町大通5丁目1番地 (〒080-0101) ※2024/7移転 | D41: 0155-42-8725 | E41: 小麦、豆類、てんさい、ブロッコリー。 | F41: 作付面積・生産量ともに国内トップクラスであり、圧倒的な数の労働力が必要。 | G41: 費用負担を最小化する補助金活用スキームと、手厚い通訳・翻訳サポートを提案。 | AG41: BREXA CrossBorder | AH41: 武田 悦郎 | AO41: =COUNTIFS(加電履歴!$F:$F,A41,加電履歴!$E:$E,"JAリスト") | AP41: =IFERROR(IF(COUNTIFS(加電履歴!$F:$F,A41,加電履歴!$E:$E,"JAリスト")=0,"",MAXIFS(加電履歴!$B:$B,加電履歴!$F:$F,A41,加電履歴!$E:$E,"JAリスト")),"") | AQ41: =IFERROR(IF(COUNTIFS(加電履歴!$F:$F,A41,加電履歴!$E:$E,"JAリスト")=0,"",INDEX(加電履歴!$I:$I,MATCH(1,(加電履歴!$F:$F=A41)*(加電履歴!$E:$E="JAリスト")*(加電履歴!$B:$B=MAXIFS(加電履歴!$B:$B,加電履歴!$F:$F,A41,加電履歴!$E:$E,"JAリスト")),0))),"")
A42: JA木野 | B42: https://ja-kino.com/ | C42: 北海道河東郡音更町木野大通西7-1 | D42: 0155-31-2143 | E42: ブロッコリー、大根、長ねぎ。 | F42: 鮮度が重要な野菜の収穫ピーク時における、確実な人員確保。 | G42: 語学教育による作業指示の正確な伝達をアピールし、収穫ロスを防ぐ高品質な労働力を提供。 | AG42: BREXA CrossBorder | AH42: 武田 悦郎 | AO42: =COUNTIFS(加電履歴!$F:$F,A42,加電履歴!$E:$E,"JAリスト") | AP42: =IFERROR(IF(COUNTIFS(加電履歴!$F:$F,A42,加電履歴!$E:$E,"JAリスト")=0,"",MAXIFS(加電履歴!$B:$B,加電履歴!$F:$F,A42,加電履歴!$E:$E,"JAリスト")),"") | AQ42: =IFERROR(IF(COUNTIFS(加電履歴!$F:$F,A42,加電履歴!$E:$E,"JAリスト")=0,"",INDEX(加電履歴!$I:$I,MATCH(1,(加電履歴!$F:$F=A42)*(加電履歴!$E:$E="JAリスト")*(加電履歴!$B:$B=MAXIFS(加電履歴!$B:$B,加電履歴!$F:$F,A42,加電履歴!$E:$E,"JAリスト")),0))),"")
A43: JA士幌町 | B43: https://www.ja-shihoro.or.jp/ | C43: 北海道河東郡士幌町字士幌西2線159番地 | D43: 01564-5-2311 | E43: じゃがいも、肉牛、酪農。直営加工施設多数。 | F43: JA直営工場があり、農場だけでなく加工工場での人員不足も深刻。 | G43: 農業と飲食料品製造業の双方の特定技能に対応できる点をアピールし、完全成果報酬で提案。 | AG43: BREXA CrossBorder | AH43: 武田 悦郎 | AO43: =COUNTIFS(加電履歴!$F:$F,A43,加電履歴!$E:$E,"JAリスト") | AP43: =IFERROR(IF(COUNTIFS(加電履歴!$F:$F,A43,加電履歴!$E:$E,"JAリスト")=0,"",MAXIFS(加電履歴!$B:$B,加電履歴!$F:$F,A43,加電履歴!$E:$E,"JAリスト")),"") | AQ43: =IFERROR(IF(COUNTIFS(加電履歴!$F:$F,A43,加電履歴!$E:$E,"JAリスト")=0,"",INDEX(加電履歴!$I:$I,MATCH(1,(加電履歴!$F:$F=A43)*(加電履歴!$E:$E="JAリスト")*(加電履歴!$B:$B=MAXIFS(加電履歴!$B:$B,加電履歴!$F:$F,A43,加電履歴!$E:$E,"JAリスト")),0))),"")
A44: JA上士幌町 | B44: https://ja-kamishihoro.or.jp/ | C44: 北海道河東郡上士幌町字上士幌東2線238 (〒080-1493) | D44: 01564-2-2131 | E44: 酪農（ギガファーム多数）、畑作。 | F44: 1000頭規模のメガファームが多く、組織的な労務管理と専門的な人材が求められる。 | G44: 企業的農業経営を行う農場に対し、人材紹介から日本語教育までワンストップのHRサービスを提供。 | AG44: BREXA CrossBorder | AH44: 武田 悦郎 | AO44: =COUNTIFS(加電履歴!$F:$F,A44,加電履歴!$E:$E,"JAリスト") | AP44: =IFERROR(IF(COUNTIFS(加電履歴!$F:$F,A44,加電履歴!$E:$E,"JAリスト")=0,"",MAXIFS(加電履歴!$B:$B,加電履歴!$F:$F,A44,加電履歴!$E:$E,"JAリスト")),"") | AQ44: =IFERROR(IF(COUNTIFS(加電履歴!$F:$F,A44,加電履歴!$E:$E,"JAリスト")=0,"",INDEX(加電履歴!$I:$I,MATCH(1,(加電履歴!$F:$F=A44)*(加電履歴!$E:$E="JAリスト")*(加電履歴!$B:$B=MAXIFS(加電履歴!$B:$B,加電履歴!$F:$F,A44,加電履歴!$E:$E,"JAリスト")),0))),"")
A45: JA鹿追町 | B45: https://www.ja-shikaoi.com/ | C45: 北海道河東郡鹿追町新町4丁目51番地 (〒081-0293) | D45: 0156-66-2131 | E45: 酪農、てんさい。バイオガスプラント推進。 | F45: 環境保全型農業を進める中で、取り組みを理解し真面目に働く人材が必要。 | G45: リスクのない成果報酬型をフックに、生活サポートや異文化理解講座を通じた高い定着率をアピール。 | AG45: BREXA CrossBorder | AH45: 武田 悦郎 | AO45: =COUNTIFS(加電履歴!$F:$F,A45,加電履歴!$E:$E,"JAリスト") | AP45: =IFERROR(IF(COUNTIFS(加電履歴!$F:$F,A45,加電履歴!$E:$E,"JAリスト")=0,"",MAXIFS(加電履歴!$B:$B,加電履歴!$F:$F,A45,加電履歴!$E:$E,"JAリスト")),"") | AQ45: =IFERROR(IF(COUNTIFS(加電履歴!$F:$F,A45,加電履歴!$E:$E,"JAリスト")=0,"",INDEX(加電履歴!$I:$I,MATCH(1,(加電履歴!$F:$F=A45)*(加電履歴!$E:$E="JAリスト")*(加電履歴!$B:$B=MAXIFS(加電履歴!$B:$B,加電履歴!$F:$F,A45,加電履歴!$E:$E,"JAリスト")),0))),"")
A46: JA新得町 | B46: https://www.ja-shintoku.or.jp/ | C46: 北海道上川郡新得町1条南3丁目1 | D46: 0156-64-5021 | E46: そば、酪農、肉牛。 | F46: そばの収穫・加工や、酪農での年間を通じた労働力不足。 | G46: 語学教育のバックグラウンドを活かし、地域とのトラブルを防ぐための事前教育の徹底を強みとする。 | AG46: BREXA CrossBorder | AH46: 武田 悦郎 | AO46: =COUNTIFS(加電履歴!$F:$F,A46,加電履歴!$E:$E,"JAリスト") | AP46: =IFERROR(IF(COUNTIFS(加電履歴!$F:$F,A46,加電履歴!$E:$E,"JAリスト")=0,"",MAXIFS(加電履歴!$B:$B,加電履歴!$F:$F,A46,加電履歴!$E:$E,"JAリスト")),"") | AQ46: =IFERROR(IF(COUNTIFS(加電履歴!$F:$F,A46,加電履歴!$E:$E,"JAリスト")=0,"",INDEX(加電履歴!$I:$I,MATCH(1,(加電履歴!$F:$F=A46)*(加電履歴!$E:$E="JAリスト")*(加電履歴!$B:$B=MAXIFS(加電履歴!$B:$B,加電履歴!$F:$F,A46,加電履歴!$E:$E,"JAリスト")),0))),"")
A47: JA阿寒 | B47: http://www.ja-akan.or.jp/ | C47: 北海道釧路市阿寒町北新町1-4-1 (〒085-0216) | D47: 0154-66-3211 | E47: 酪農、肉牛、エゾシカ肉加工。 | F47: 大規模酪農地帯であり、搾乳作業など年間を通じて安定した人員が必要。 | G47: 補助金採択を条件とすることで、初期費用に悩む酪農家へのアプローチを容易にする。 | AG47: BREXA CrossBorder | AH47: 武田 悦郎 | AO47: =COUNTIFS(加電履歴!$F:$F,A47,加電履歴!$E:$E,"JAリスト") | AP47: =IFERROR(IF(COUNTIFS(加電履歴!$F:$F,A47,加電履歴!$E:$E,"JAリスト")=0,"",MAXIFS(加電履歴!$B:$B,加電履歴!$F:$F,A47,加電履歴!$E:$E,"JAリスト")),"") | AQ47: =IFERROR(IF(COUNTIFS(加電履歴!$F:$F,A47,加電履歴!$E:$E,"JAリスト")=0,"",INDEX(加電履歴!$I:$I,MATCH(1,(加電履歴!$F:$F=A47)*(加電履歴!$E:$E="JAリスト")*(加電履歴!$B:$B=MAXIFS(加電履歴!$B:$B,加電履歴!$F:$F,A47,加電履歴!$E:$E,"JAリスト")),0))),"")
A48: JAしべちゃ | B48: https://www.sip.jp/~ja-shibecya/ | C48: 北海道川上郡標茶町開運9丁目6番地 (〒088-2311) | D48: 015-485-2103 | E48: 酪農（広大な放牧地）、肉牛。 | F48: 広大な面積を誇るため、孤立しがちな環境における外国人材のメンタルケアが課題。 | G48: 定期的な訪問や「やさしい日本語講座」を通じた細やかなメンタルサポート体制を強調する。 | AG48: BREXA CrossBorder | AH48: 武田 悦郎 | AO48: =COUNTIFS(加電履歴!$F:$F,A48,加電履歴!$E:$E,"JAリスト") | AP48: =IFERROR(IF(COUNTIFS(加電履歴!$F:$F,A48,加電履歴!$E:$E,"JAリスト")=0,"",MAXIFS(加電履歴!$B:$B,加電履歴!$F:$F,A48,加電履歴!$E:$E,"JAリスト")),"") | AQ48: =IFERROR(IF(COUNTIFS(加電履歴!$F:$F,A48,加電履歴!$E:$E,"JAリスト")=0,"",INDEX(加電履歴!$I:$I,MATCH(1,(加電履歴!$F:$F=A48)*(加電履歴!$E:$E="JAリスト")*(加電履歴!$B:$B=MAXIFS(加電履歴!$B:$B,加電履歴!$F:$F,A48,加電履歴!$E:$E,"JAリスト")),0))),"")
...

Sheet 畜種農業
A1: エリア | B1: 企業名 | C1: ホームページ | D1: 住所 | E1: 電話番号 | F1: 地域の農業特徴・特産品情報 | G1: 想定される課題・アプローチのポイント | H1: 提案の切り口（自社サービス・強み） | I1: 担当部署 | J1: 役職 | K1: 担当者 | L1: 活用状況 | M1: 実習人数 | N1: 実習_国籍 | O1: 特技人数 | P1: 特技_国籍 | Q1: 既存状況 | R1: 営業状況 | S1: ステータス | T1: 進捗 | U1: 初回訪問日 | V1: 最終コンタクト日 | W1: 最終経過日数 | X1: 訪問履歴 | Y1: 最終アクション（日付・結果/詳細） | Z1: 日付 | AA1: 行動 | AB1: 次回アクション予定 | AC1: 予定日 | AD1: 連携元 | AE1: 連携元所属 | AF1: 連携者 | AG1: 連携先 | AH1: 担当所属 | AI1: 営業担当 | AJ1: 受注日 | AK1: 受注内容 | AL1: 配属予定日 | AM1: 受注_国籍 | AN1: 受注_人数 | AO1: 状況 | AQ1: 加電回数 | AR1: 最終加電日 | AS1: 最終結果
A2: 道央 | B2: 株式会社Kalm角山 | C2: https://www.kalm.co.jp/ | D2: 北海道江別市角山491 | E2: 011-378-6858 | F2: 都市型メガファーム/搾乳ロボット導入 | G2: 規模拡大に伴うオペレーター不足 | H2: 初期採用費用を抑え現場の即戦力となる特定技能人材をご提案 | I2: 経営企画部 | J2: 代表取締役 | K2: 川口谷 仁 | L2: 導入済 | Q2: 未開拓 | R2: ターゲット | S2: リストアップ | AH2: 営業推進部 | AI2: 武田 悦郎 | AP2: 未定 | AQ2: =COUNTIFS(加電履歴!$F:$F,B2,加電履歴!$E:$E,"畜種農業") | AR2: =IFERROR(IF(COUNTIFS(加電履歴!$F:$F,B2,加電履歴!$E:$E,"畜種農業")=0,"",MAXIFS(加電履歴!$B:$B,加電履歴!$F:$F,B2,加電履歴!$E:$E,"畜種農業")),"") | AS2: =IFERROR(IF(COUNTIFS(加電履歴!$F:$F,B2,加電履歴!$E:$E,"畜種農業")=0,"",INDEX(加電履歴!$I:$I,MATCH(1,(加電履歴!$F:$F=B2)*(加電履歴!$E:$E="畜種農業")*(加電履歴!$B:$B=MAXIFS(加電履歴!$B:$B,加電履歴!$F:$F,B2,加電履歴!$E:$E,"畜種農業")),0))),"")
A3: 道央 | B3: 株式会社町村農場 | C3: http://www.machimura.co.jp/ | D3: 北海道江別市篠津183番地 (〒067-0055) | E3: 011-382-2155 | F3: 自社ブランド乳製品の製造直販 | G3: 農場作業と加工販売の兼務による負担 | H3: 採用コストゼロで即戦力を配置し既存社員を販売業務へシフトさせる提案 | I3: 経営陣 | J3: 代表取締役 | K3: 町村 均 | L3: 未確認 | Q3: 未開拓 | R3: ターゲット | S3: リストアップ | AH3: 営業推進部 | AI3: 武田 悦郎 | AP3: 未定 | AQ3: =COUNTIFS(加電履歴!$F:$F,B3,加電履歴!$E:$E,"畜種農業") | AR3: =IFERROR(IF(COUNTIFS(加電履歴!$F:$F,B3,加電履歴!$E:$E,"畜種農業")=0,"",MAXIFS(加電履歴!$B:$B,加電履歴!$F:$F,B3,加電履歴!$E:$E,"畜種農業")),"") | AS3: =IFERROR(IF(COUNTIFS(加電履歴!$F:$F,B3,加電履歴!$E:$E,"畜種農業")=0,"",INDEX(加電履歴!$I:$I,MATCH(1,(加電履歴!$F:$F=B3)*(加電履歴!$E:$E="畜種農業")*(加電履歴!$B:$B=MAXIFS(加電履歴!$B:$B,加電履歴!$F:$F,B3,加電履歴!$E:$E,"畜種農業")),0))),"")
A4: 道央 | B4: おおやファーム株式会社 | C4: https://ooya-farm.com/ | D4: 北海道千歳市駒里2297 (〒066-0011) | E4: 0123-40-6175 | F4: ブランド豚「う米豚」一貫生産 | G4: 養豚の重労働による若手人材の定着難 | H4: 養豚現場に適応できる特定技能人材を余計な採用コストなしで即戦力として提供 | I4: 管理部 | J4: 代表取締役社長 | K4: 大矢 智彰 | L4: 未確認 | Q4: 未開拓 | R4: ターゲット | S4: リストアップ | AH4: 営業推進部 | AI4: 武田 悦郎 | AP4: 未定 | AQ4: =COUNTIFS(加電履歴!$F:$F,B4,加電履歴!$E:$E,"畜種農業") | AR4: =IFERROR(IF(COUNTIFS(加電履歴!$F:$F,B4,加電履歴!$E:$E,"畜種農業")=0,"",MAXIFS(加電履歴!$B:$B,加電履歴!$F:$F,B4,加電履歴!$E:$E,"畜種農業")),"") | AS4: =IFERROR(IF(COUNTIFS(加電履歴!$F:$F,B4,加電履歴!$E:$E,"畜種農業")=0,"",INDEX(加電履歴!$I:$I,MATCH(1,(加電履歴!$F:$F=B4)*(加電履歴!$E:$E="畜種農業")*(加電履歴!$B:$B=MAXIFS(加電履歴!$B:$B,加電履歴!$F:$F,B4,加電履歴!$E:$E,"畜種農業")),0))),"")
A5: 道央 | B5: 有限会社浅野農場 | C5: https://asanofarm.com/ | D5: 北海道石狩郡当別町字上当別2190番地 (〒061-0207) | E5: 0133-22-4129 | F5: 大規模SPF豚生産/複合経営 | G5: 繁忙期が重なる際の労働力不足 | H5: 複合経営に対応できる柔軟な即戦力人材を採用コストを抑えて提供 | I5: 管理部 | J5: 代表取締役 | K5: 浅野 政輝 | L5: 未確認 | Q5: 未開拓 | R5: ターゲット | S5: リストアップ | AH5: 営業推進部 | AI5: 武田 悦郎 | AP5: 未定 | AQ5: =COUNTIFS(加電履歴!$F:$F,B5,加電履歴!$E:$E,"畜種農業") | AR5: =IFERROR(IF(COUNTIFS(加電履歴!$F:$F,B5,加電履歴!$E:$E,"畜種農業")=0,"",MAXIFS(加電履歴!$B:$B,加電履歴!$F:$F,B5,加電履歴!$E:$E,"畜種農業")),"") | AS5: =IFERROR(IF(COUNTIFS(加電履歴!$F:$F,B5,加電履歴!$E:$E,"畜種農業")=0,"",INDEX(加電履歴!$I:$I,MATCH(1,(加電履歴!$F:$F=B5)*(加電履歴!$E:$E="畜種農業")*(加電履歴!$B:$B=MAXIFS(加電履歴!$B:$B,加電履歴!$F:$F,B5,加電履歴!$E:$E,"畜種農業")),0))),"")
A6: 道央 | B6: 有限会社永光農園 | C6: https://nagamitsufarm.com/ | D6: 北海道札幌市清田区有明216番地 | E6: 011-886-7204 | F6: 平飼い養鶏/スイーツ店運営 | G6: 集卵や給餌作業と販売スタッフ不足 | H6: 養鶏ルーティンを即戦力に任せ代表が店舗運営に専念できる体制構築 | I6: 本社 | J6: 代表取締役 | K6: 永光 洋明 | L6: 未確認 | Q6: 未開拓 | R6: ターゲット | S6: リストアップ | AH6: 営業推進部 | AI6: 武田 悦郎 | AP6: 未定 | AQ6: =COUNTIFS(加電履歴!$F:$F,B6,加電履歴!$E:$E,"畜種農業") | AR6: =IFERROR(IF(COUNTIFS(加電履歴!$F:$F,B6,加電履歴!$E:$E,"畜種農業")=0,"",MAXIFS(加電履歴!$B:$B,加電履歴!$F:$F,B6,加電履歴!$E:$E,"畜種農業")),"") | AS6: =IFERROR(IF(COUNTIFS(加電履歴!$F:$F,B6,加電履歴!$E:$E,"畜種農業")=0,"",INDEX(加電履歴!$I:$I,MATCH(1,(加電履歴!$F:$F=B6)*(加電履歴!$E:$E="畜種農業")*(加電履歴!$B:$B=MAXIFS(加電履歴!$B:$B,加電履歴!$F:$F,B6,加電履歴!$E:$E,"畜種農業")),0))),"")
A7: 道央 | B7: 酪農体験むらかみ牧場 | C7: https://murakami-farm.com/ | D7: 北海道恵庭市戸磯156番地 | E7: 080-6061-9966 | F7: 観光牧場/自家製牛乳販売 | G7: 観光客対応と通常の飼養管理の両立 | H7: バックヤードの飼養管理を即戦力が担うことで接客観光サービス品質を向上 | I7: 経営陣 | J7: 代表 | K7: 村上 隆彦 | L7: 未確認 | Q7: 未開拓 | R7: ターゲット | S7: リストアップ | AH7: 営業推進部 | AI7: 武田 悦郎 | AP7: 未定 | AQ7: =COUNTIFS(加電履歴!$F:$F,B7,加電履歴!$E:$E,"畜種農業") | AR7: =IFERROR(IF(COUNTIFS(加電履歴!$F:$F,B7,加電履歴!$E:$E,"畜種農業")=0,"",MAXIFS(加電履歴!$B:$B,加電履歴!$F:$F,B7,加電履歴!$E:$E,"畜種農業")),"") | AS7: =IFERROR(IF(COUNTIFS(加電履歴!$F:$F,B7,加電履歴!$E:$E,"畜種農業")=0,"",INDEX(加電履歴!$I:$I,MATCH(1,(加電履歴!$F:$F=B7)*(加電履歴!$E:$E="畜種農業")*(加電履歴!$B:$B=MAXIFS(加電履歴!$B:$B,加電履歴!$F:$F,B7,加電履歴!$E:$E,"畜種農業")),0))),"")
A8: 道央 | B8: 株式会社北海道酪農公社 | C8: https://www.mainichi-milk.co.jp/ | D8: 北海道江別市工栄町16 (〒067-0051) | E8: 011-384-6930 | F8: 江別市拠点の乳製品製造 | G8: 生乳処理量の変動に応じた人員配置 | H8: 製造現場で即戦力となる人材を活用し採用コストを抑制しながらラインを安定化 | I8: 本社 | J8: 代表取締役社長 | K8: 垣原 徳彰 | L8: 未確認 | Q8: 未開拓 | R8: ターゲット | S8: リストアップ | AH8: 営業推進部 | AI8: 武田 悦郎 | AP8: 未定 | AQ8: =COUNTIFS(加電履歴!$F:$F,B8,加電履歴!$E:$E,"畜種農業") | AR8: =IFERROR(IF(COUNTIFS(加電履歴!$F:$F,B8,加電履歴!$E:$E,"畜種農業")=0,"",MAXIFS(加電履歴!$B:$B,加電履歴!$F:$F,B8,加電履歴!$E:$E,"畜種農業")),"") | AS8: =IFERROR(IF(COUNTIFS(加電履歴!$F:$F,B8,加電履歴!$E:$E,"畜種農業")=0,"",INDEX(加電履歴!$I:$I,MATCH(1,(加電履歴!$F:$F=B8)*(加電履歴!$E:$E="畜種農業")*(加電履歴!$B:$B=MAXIFS(加電履歴!$B:$B,加電履歴!$F:$F,B8,加電履歴!$E:$E,"畜種農業")),0))),"")
A9: 道央 | B9: 株式会社太田ファーム | C9: https://ohtafarm-tamago.com/ | D9: 北海道江別市角山189 (〒067-0052) | E9: 011-383-8245 | F9: 純国産鶏もみじ等の平飼い養鶏 | G9: 毎日の集卵と鶏舎管理の負担軽減 | H9: 養鶏特有の朝夕作業に即戦力として対応可能な特定技能人材の活用提案 | I9: 経営陣 | J9: 代表取締役 | K9: 太田 定昭 | L9: 未確認 | Q9: 未開拓 | R9: ターゲット | S9: リストアップ | AH9: 営業推進部 | AI9: 武田 悦郎 | AP9: 未定 | AQ9: =COUNTIFS(加電履歴!$F:$F,B9,加電履歴!$E:$E,"畜種農業") | AR9: =IFERROR(IF(COUNTIFS(加電履歴!$F:$F,B9,加電履歴!$E:$E,"畜種農業")=0,"",MAXIFS(加電履歴!$B:$B,加電履歴!$F:$F,B9,加電履歴!$E:$E,"畜種農業")),"") | AS9: =IFERROR(IF(COUNTIFS(加電履歴!$F:$F,B9,加電履歴!$E:$E,"畜種農業")=0,"",INDEX(加電履歴!$I:$I,MATCH(1,(加電履歴!$F:$F=B9)*(加電履歴!$E:$E="畜種農業")*(加電履歴!$B:$B=MAXIFS(加電履歴!$B:$B,加電履歴!$F:$F,B9,加電履歴!$E:$E,"畜種農業")),0))),"")
A10: 道央 | B10: 株式会社ユートピアアグリカルチャー (本店:日高町豊郷916-6) | C10: https://www.utopiaagriculture.com/ | D10: 北海道札幌市中央区北1条西10丁目1-21 ユーネットビル2階 ※札幌事務所 | E10: 011-590-4195 | F10: 放牧酪農と平飼い養鶏 | G10: 放牧管理や養鶏作業の担い手不足 | H10: 現場で即戦力となる人材を採用コストなしで提供する提案 | I10: 経営陣 | J10: 代表取締役 | K10: 長沼 真太郎 | L10: 未確認 | Q10: 未開拓 | R10: ターゲット | S10: リストアップ | AH10: 営業推進部 | AI10: 武田 悦郎 | AP10: 未定 | AQ10: =COUNTIFS(加電履歴!$F:$F,B10,加電履歴!$E:$E,"畜種農業") | AR10: =IFERROR(IF(COUNTIFS(加電履歴!$F:$F,B10,加電履歴!$E:$E,"畜種農業")=0,"",MAXIFS(加電履歴!$B:$B,加電履歴!$F:$F,B10,加電履歴!$E:$E,"畜種農業")),"") | AS10: =IFERROR(IF(COUNTIFS(加電履歴!$F:$F,B10,加電履歴!$E:$E,"畜種農業")=0,"",INDEX(加電履歴!$I:$I,MATCH(1,(加電履歴!$F:$F=B10)*(加電履歴!$E:$E="畜種農業")*(加電履歴!$B:$B=MAXIFS(加電履歴!$B:$B,加電履歴!$F:$F,B10,加電履歴!$E:$E,"畜種農業")),0))),"")
A11: 道央 | B11: 有限会社大塚農場 | C11: https://www.oh-farm.co.jp/ | D11: 北海道石狩郡当別町字東裏3122番地 | E11: ※公式サイト経由 / 0133-23-2831 ※要確認 | F11: 特別栽培農産物と畜産の複合経営 | G11: 多品目栽培と畜産管理の同時並行による多忙 | H11: 複合農業の多様な作業に即戦力で対応できる外国人材の導入提案 | I11: 管理部 | J11: 代表取締役 | K11: 大塚 慎太郎 | L11: 未確認 | Q11: 未開拓 | R11: ターゲット | S11: リストアップ | AH11: 営業推進部 | AI11: 武田 悦郎 | AP11: 未定 | AQ11: =COUNTIFS(加電履歴!$F:$F,B11,加電履歴!$E:$E,"畜種農業") | AR11: =IFERROR(IF(COUNTIFS(加電履歴!$F:$F,B11,加電履歴!$E:$E,"畜種農業")=0,"",MAXIFS(加電履歴!$B:$B,加電履歴!$F:$F,B11,加電履歴!$E:$E,"畜種農業")),"") | AS11: =IFERROR(IF(COUNTIFS(加電履歴!$F:$F,B11,加電履歴!$E:$E,"畜種農業")=0,"",INDEX(加電履歴!$I:$I,MATCH(1,(加電履歴!$F:$F=B11)*(加電履歴!$E:$E="畜種農業")*(加電履歴!$B:$B=MAXIFS(加電履歴!$B:$B,加電履歴!$F:$F,B11,加電履歴!$E:$E,"畜種農業")),0))),"")
A12: 道央 | B12: 有限会社山中畜産 | C12: http://www.yamanaka-pork.com/ | D12: 北海道夕張郡長沼町西2線北1番地 (〒069-1318) | E12: 0123-88-2146 | F12: SPF認定豚生産 | G12: 母豚の大規模管理における人員確保 | H12: 大規模養豚のルーティンワークを即戦力として支える特定技能人材の提供 | I12: 本社 | J12: 代表取締役 | K12: 山中 克人 | L12: 未確認 | Q12: 未開拓 | R12: ターゲット | S12: リストアップ | AH12: 営業推進部 | AI12: 武田 悦郎 | AP12: 未定 | AQ12: =COUNTIFS(加電履歴!$F:$F,B12,加電履歴!$E:$E,"畜種農業") | AR12: =IFERROR(IF(COUNTIFS(加電履歴!$F:$F,B12,加電履歴!$E:$E,"畜種農業")=0,"",MAXIFS(加電履歴!$B:$B,加電履歴!$F:$F,B12,加電履歴!$E:$E,"畜種農業")),"") | AS12: =IFERROR(IF(COUNTIFS(加電履歴!$F:$F,B12,加電履歴!$E:$E,"畜種農業")=0,"",INDEX(加電履歴!$I:$I,MATCH(1,(加電履歴!$F:$F=B12)*(加電履歴!$E:$E="畜種農業")*(加電履歴!$B:$B=MAXIFS(加電履歴!$B:$B,加電履歴!$F:$F,B12,加電履歴!$E:$E,"畜種農業")),0))),"")
A13: 道央 | B13: 有限会社福屋牧場 | C13: https://www.elmlane.co.jp/ | D13: 北海道恵庭市上山口653-4 (〒061-1404) | E13: 0123-32-2157 | F13: コンテスト受賞歴のある酪農/ブリーダー | G13: 共進会レベルの牛群管理と日常作業の両立 | H13: 高い技術要求に応えるポテンシャルのある人材を即戦力として定着させる提案 | I13: 経営陣 | J13: 代表取締役 | K13: 福屋 栄人 | L13: 未確認 | Q13: 未開拓 | R13: ターゲット | S13: リストアップ | AH13: 営業推進部 | AI13: 武田 悦郎 | AP13: 未定 | AQ13: =COUNTIFS(加電履歴!$F:$F,B13,加電履歴!$E:$E,"畜種農業") | AR13: =IFERROR(IF(COUNTIFS(加電履歴!$F:$F,B13,加電履歴!$E:$E,"畜種農業")=0,"",MAXIFS(加電履歴!$B:$B,加電履歴!$F:$F,B13,加電履歴!$E:$E,"畜種農業")),"") | AS13: =IFERROR(IF(COUNTIFS(加電履歴!$F:$F,B13,加電履歴!$E:$E,"畜種農業")=0,"",INDEX(加電履歴!$I:$I,MATCH(1,(加電履歴!$F:$F=B13)*(加電履歴!$E:$E="畜種農業")*(加電履歴!$B:$B=MAXIFS(加電履歴!$B:$B,加電履歴!$F:$F,B13,加電履歴!$E:$E,"畜種農業")),0))),"")
... A26: 道央 | B26: アースドリーム角山農場 (トンデンファーム) | C26: https://www.tondenfarm.co.jp/ | D26: 北海道江別市元野幌584番地1 | E26: 011-391-2500 | F26: 観光体験牧場/アルパカやミニ豚飼育 | G26: 観光客対応と多種多様な動物の飼育負担 | H26: 観光エリア外でのバックヤード飼育管理を即戦力に任せる体制構築 | I26: 農場管理部 | J26: 代表 | K26: 不明 | L26: 未確認 | Q26: 未開拓 | R26: ターゲット | S26: リストアップ | AH26: 営業推進部 | AI26: 武田 悦郎 | AP26: 未定 | AQ26: =COUNTIFS(加電履歴!$F:$F,B26,加電履歴!$E:$E,"畜種農業") | AR26: =IFERROR(IF(COUNTIFS(加電履歴!$F:$F,B26,加電履歴!$E:$E,"畜種農業")=0,"",MAXIFS(加電履歴!$B:$B,加電履歴!$F:$F,B26,加電履歴!$E:$E,"畜種農業")),"") | AS26: =IFERROR(IF(COUNTIFS(加電履歴!$F:$F,B26,加電履歴!$E:$E,"畜種農業")=0,"",INDEX(加電履歴!$I:$I,MATCH(1,(加電履歴!$F:$F=B26)*(加電履歴!$E:$E="畜種農業")*(加電履歴!$B:$B=MAXIFS(加電履歴!$B:$B,加電履歴!$F:$F,B26,加電履歴!$E:$E,"畜種農業")),0))),"")
A27: 道央 | B27: 千歳市営牧場 (公益財団法人道央農業振興公社) | D27: 北海道千歳市駒里1032番地の1 (駒里地区, 220ha) | E27: 0123-23-4170 | F27: 公共牧野/育成牛の通年預託 | G27: 広大な牧草地と育成牛管理の省力化 | H27: 公共施設の安定稼働を即戦力の特定技能人材で支援する提案 | I27: 管理部 | J27: 管理者 | K27: 不明 | L27: 未確認 | Q27: 未開拓 | R27: ターゲット | S27: リストアップ | AH27: 営業推進部 | AI27: 武田 悦郎 | AP27: 未定 | AQ27: =COUNTIFS(加電履歴!$F:$F,B27,加電履歴!$E:$E,"畜種農業") | AR27: =IFERROR(IF(COUNTIFS(加電履歴!$F:$F,B27,加電履歴!$E:$E,"畜種農業")=0,"",MAXIFS(加電履歴!$B:$B,加電履歴!$F:$F,B27,加電履歴!$E:$E,"畜種農業")),"") | AS27: =IFERROR(IF(COUNTIFS(加電履歴!$F:$F,B27,加電履歴!$E:$E,"畜種農業")=0,"",INDEX(加電履歴!$I:$I,MATCH(1,(加電履歴!$F:$F=B27)*(加電履歴!$E:$E="畜種農業")*(加電履歴!$B:$B=MAXIFS(加電履歴!$B:$B,加電履歴!$F:$F,B27,加電履歴!$E:$E,"畜種農業")),0))),"")
A28: 道央 | B28: 石狩ひつじ牧場 | D28: 北海道石狩市樽川485-1 (〒061-3251) | E28: 080-4505-1935 (スタッフ) / 070-6601-1116 (代表) | F28: 観光牧場/羊乳チーズ製造 | G28: 羊の飼育と観光・チーズ製造の兼務負担 | H28: 飼育管理を即戦力が担うことで代表が加工・接客に専念できる体制構築 | I28: 経営陣 | J28: 代表 | K28: 不明 | L28: 未確認 | Q28: 未開拓 | R28: ターゲット | S28: リストアップ | AH28: 営業推進部 | AI28: 武田 悦郎 | AP28: 未定 | AQ28: =COUNTIFS(加電履歴!$F:$F,B28,加電履歴!$E:$E,"畜種農業") | AR28: =IFERROR(IF(COUNTIFS(加電履歴!$F:$F,B28,加電履歴!$E:$E,"畜種農業")=0,"",MAXIFS(加電履歴!$B:$B,加電履歴!$F:$F,B28,加電履歴!$E:$E,"畜種農業")),"") | AS28: =IFERROR(IF(COUNTIFS(加電履歴!$F:$F,B28,加電履歴!$E:$E,"畜種農業")=0,"",INDEX(加電履歴!$I:$I,MATCH(1,(加電履歴!$F:$F=B28)*(加電履歴!$E:$E="畜種農業")*(加電履歴!$B:$B=MAXIFS(加電履歴!$B:$B,加電履歴!$F:$F,B28,加電履歴!$E:$E,"畜種農業")),0))),"")
A29: 道央 | B29: 有限会社大塚ファーム | D29: 北海道石狩郡新篠津村第36線南42番地 | E29: 0126-57-2573 | F29: 有機農業および関連事業 | G29: 農福連携と複合的な作業の効率化 | H29: 多様な作業に即戦力で対応する人材の提供 | I29: 経営陣 | J29: 代表 | K29: 大塚 氏 | L29: 未確認 | Q29: 未開拓 | R29: ターゲット | S29: リストアップ | AH29: 営業推進部 | AI29: 武田 悦郎 | AP29: 未定 | AQ29: =COUNTIFS(加電履歴!$F:$F,B29,加電履歴!$E:$E,"畜種農業") | AR29: =IFERROR(IF(COUNTIFS(加電履歴!$F:$F,B29,加電履歴!$E:$E,"畜種農業")=0,"",MAXIFS(加電履歴!$B:$B,加電履歴!$F:$F,B29,加電履歴!$E:$E,"畜種農業")),"") | AS29: =IFERROR(IF(COUNTIFS(加電履歴!$F:$F,B29,加電履歴!$E:$E,"畜種農業")=0,"",INDEX(加電履歴!$I:$I,MATCH(1,(加電履歴!$F:$F=B29)*(加電履歴!$E:$E="畜種農業")*(加電履歴!$B:$B=MAXIFS(加電履歴!$B:$B,加電履歴!$F:$F,B29,加電履歴!$E:$E,"畜種農業")),0))),"")
A30: 道央 | B30: 株式会社JAKE | D30: 北海道岩見沢市下志文町24-11 | E30: 0126-26-3340 | F30: 養鶏・有機穀物生産 | G30: 複合経営の労働力分散 | H30: 養鶏部門への即戦力配置による生産性向上 | I30: 本社 | J30: 代表 | K30: 不明 | L30: 未確認 | Q30: 未開拓 | R30: ターゲット | S30: リストアップ | AH30: 営業推進部 | AI30: 武田 悦郎 | AP30: 未定 | AQ30: =COUNTIFS(加電履歴!$F:$F,B30,加電履歴!$E:$E,"畜種農業") | AR30: =IFERROR(IF(COUNTIFS(加電履歴!$F:$F,B30,加電履歴!$E:$E,"畜種農業")=0,"",MAXIFS(加電履歴!$B:$B,加電履歴!$F:$F,B30,加電履歴!$E:$E,"畜種農業")),"") | AS30: =IFERROR(IF(COUNTIFS(加電履歴!$F:$F,B30,加電履歴!$E:$E,"畜種農業")=0,"",INDEX(加電履歴!$I:$I,MATCH(1,(加電履歴!$F:$F=B30)*(加電履歴!$E:$E="畜種農業")*(加電履歴!$B:$B=MAXIFS(加電履歴!$B:$B,加電履歴!$F:$F,B30,加電履歴!$E:$E,"畜種農業")),0))),"")
A31: 道央 | B31: 橋田牧場 | D31: 北海道恵庭市(えにあす関連) | E31: 0123-25-5727(参考) | F31: 恵庭市における酪農経営 | G31: 安定的な搾乳作業の担い手確保 | H31: 採用コストゼロで即戦力を配置し安定した搾乳オペレーションを実現 | I31: 経営陣 | J31: 代表(指導農業士) | K31: 橋田 武 | L31: 未確認 | Q31: 未開拓 | R31: ターゲット | S31: リストアップ | AH31: 営業推進部 | AI31: 武田 悦郎 | AP31: 未定 | AQ31: =COUNTIFS(加電履歴!$F:$F,B31,加電履歴!$E:$E,"畜種農業") | AR31: =IFERROR(IF(COUNTIFS(加電履歴!$F:$F,B31,加電履歴!$E:$E,"畜種農業")=0,"",MAXIFS(加電履歴!$B:$B,加電履歴!$F:$F,B31,加電履歴!$E:$E,"畜種農業")),"") | AS31: =IFERROR(IF(COUNTIFS(加電履歴!$F:$F,B31,加電履歴!$E:$E,"畜種農業")=0,"",INDEX(加電履歴!$I:$I,MATCH(1,(加電履歴!$F:$F=B31)*(加電履歴!$E:$E="畜種農業")*(加電履歴!$B:$B=MAXIFS(加電履歴!$B:$B,加電履歴!$F:$F,B31,加電履歴!$E:$E,"畜種農業")),0))),"")
A32: 道央 | B32: 石橋牧場 | D32: 北海道北広島市 | E32: 不明 | F32: 北広島市における酪農経営 | G32: 都市近郊での継続的な酪農スタッフ確保 | H32: 都市近郊型の酪農環境に適応できる即戦力人材の提供 | I32: 経営陣 | J32: 代表(指導農業士) | K32: 石橋 茂信 | L32: 未確認 | Q32: 未開拓 | R32: ターゲット | S32: リストアップ | AH32: 営業推進部 | AI32: 武田 悦郎 | AP32: 未定 | AQ32: =COUNTIFS(加電履歴!$F:$F,B32,加電履歴!$E:$E,"畜種農業") | AR32: =IFERROR(IF(COUNTIFS(加電履歴!$F:$F,B32,加電履歴!$E:$E,"畜種農業")=0,"",MAXIFS(加電履歴!$B:$B,加電履歴!$F:$F,B32,加電履歴!$E:$E,"畜種農業")),"") | AS32: =IFERROR(IF(COUNTIFS(加電履歴!$F:$F,B32,加電履歴!$E:$E,"畜種農業")=0,"",INDEX(加電履歴!$I:$I,MATCH(1,(加電履歴!$F:$F=B32)*(加電履歴!$E:$E="畜種農業")*(加電履歴!$B:$B=MAXIFS(加電履歴!$B:$B,加電履歴!$F:$F,B32,加電履歴!$E:$E,"畜種農業")),0))),"")
A33: 道央 | B33: 藤本農場 | D33: 北海道千歳市 | E33: 不明 | F33: 酪農と畑作の複合経営 | G33: 複合経営における季節ごとの労働ピークへの対応 | H33: 酪農と畑作のハイブリッド作業に即戦力として対応する人材提案 | I33: 経営陣 | J33: 代表(指導農業士) | K33: 藤本 謹也 | L33: 未確認 | Q33: 未開拓 | R33: ターゲット | S33: リストアップ | AH33: 営業推進部 | AI33: 武田 悦郎 | AP33: 未定 | AQ33: =COUNTIFS(加電履歴!$F:$F,B33,加電履歴!$E:$E,"畜種農業") | AR33: =IFERROR(IF(COUNTIFS(加電履歴!$F:$F,B33,加電履歴!$E:$E,"畜種農業")=0,"",MAXIFS(加電履歴!$B:$B,加電履歴!$F:$F,B33,加電履歴!$E:$E,"畜種農業")),"") | AS33: =IFERROR(IF(COUNTIFS(加電履歴!$F:$F,B33,加電履歴!$E:$E,"畜種農業")=0,"",INDEX(加電履歴!$I:$I,MATCH(1,(加電履歴!$F:$F=B33)*(加電履歴!$E:$E="畜種農業")*(加電履歴!$B:$B=MAXIFS(加電履歴!$B:$B,加電履歴!$F:$F,B33,加電履歴!$E:$E,"畜種農業")),0))),"")
A34: 道央 | B34: 寺山農場 | D34: 北海道石狩市 | E34: 不明 | F34: 肉用牛・稲作・畑作の複合経営 | G34: 肉用牛の飼養管理と農繁期の両立 | H34: 肉牛管理の基本作業を即戦力に任せ代表が経営に専念できる体制構築 | I34: 経営陣 | J34: 代表(指導農業士) | K34: 寺山 広司 | L34: 未確認 | Q34: 未開拓 | R34: ターゲット | S34: リストアップ | AH34: 営業推進部 | AI34: 武田 悦郎 | AP34: 未定 | AQ34: =COUNTIFS(加電履歴!$F:$F,B34,加電履歴!$E:$E,"畜種農業") | AR34: =IFERROR(IF(COUNTIFS(加電履歴!$F:$F,B34,加電履歴!$E:$E,"畜種農業")=0,"",MAXIFS(加電履歴!$B:$B,加電履歴!$F:$F,B34,加電履歴!$E:$E,"畜種農業")),"") | AS34: =IFERROR(IF(COUNTIFS(加電履歴!$F:$F,B34,加電履歴!$E:$E,"畜種農業")=0,"",INDEX(加電履歴!$I:$I,MATCH(1,(加電履歴!$F:$F=B34)*(加電履歴!$E:$E="畜種農業")*(加電履歴!$B:$B=MAXIFS(加電履歴!$B:$B,加電履歴!$F:$F,B34,加電履歴!$E:$E,"畜種農業")),0))),"")
A35: 道南 | B35: 日本クリーンファーム株式会社 道南事業所 | D35: 北海道二海郡八雲町 | E35: 不明 | F35: 大規模養豚/道南トップクラスの生産量 | G35: 大規模施設の清掃と衛生管理の負担増 | H35: 余計な採用コストなしで現場の即戦力となる特定技能人材を配置し安定稼働を支援 | I35: 管理部 | J35: 代表 | K35: 不明 | L35: 未確認 | Q35: 未開拓 | R35: ターゲット | S35: リストアップ | AH35: 営業推進部 | AI35: 武田 悦郎 | AP35: 未定 | AQ35: =COUNTIFS(加電履歴!$F:$F,B35,加電履歴!$E:$E,"畜種農業") | AR35: =IFERROR(IF(COUNTIFS(加電履歴!$F:$F,B35,加電履歴!$E:$E,"畜種農業")=0,"",MAXIFS(加電履歴!$B:$B,加電履歴!$F:$F,B35,加電履歴!$E:$E,"畜種農業")),"") | AS35: =IFERROR(IF(COUNTIFS(加電履歴!$F:$F,B35,加電履歴!$E:$E,"畜種農業")=0,"",INDEX(加電履歴!$I:$I,MATCH(1,(加電履歴!$F:$F=B35)*(加電履歴!$E:$E="畜種農業")*(加電履歴!$B:$B=MAXIFS(加電履歴!$B:$B,加電履歴!$F:$F,B35,加電履歴!$E:$E,"畜種農業")),0))),"")
A36: 道南 | B36: 株式会社山邊畜産 | D36: 北海道函館市 | E36: 0138-58-3715 | F36: 養豚/渡島エリアの安定供給 | G36: 日々の豚舎管理と従業員の高齢化 | H36: 即戦力を投入しベテラン社員の負担を軽減する体制づくり | I36: 経営陣 | J36: 代表取締役 | K36: 山邊 氏 | L36: 未確認 | Q36: 未開拓 | R36: ターゲット | S36: リストアップ | AH36: 営業推進部 | AI36: 武田 悦郎 | AP36: 未定 | AQ36: =COUNTIFS(加電履歴!$F:$F,B36,加電履歴!$E:$E,"畜種農業") | AR36: =IFERROR(IF(COUNTIFS(加電履歴!$F:$F,B36,加電履歴!$E:$E,"畜種農業")=0,"",MAXIFS(加電履歴!$B:$B,加電履歴!$F:$F,B36,加電履歴!$E:$E,"畜種農業")),"") | AS36: =IFERROR(IF(COUNTIFS(加電履歴!$F:$F,B36,加電履歴!$E:$E,"畜種農業")=0,"",INDEX(加電履歴!$I:$I,MATCH(1,(加電履歴!$F:$F=B36)*(加電履歴!$E:$E="畜種農業")*(加電履歴!$B:$B=MAXIFS(加電履歴!$B:$B,加電履歴!$F:$F,B36,加電履歴!$E:$E,"畜種農業")),0))),"")
A37: 道南 | B37: 有限会社サクセス森 | D37: 北海道茅部郡森町 | E37: 不明 | F37: 養豚経営 | G37: 若手人材の不足による生産体制の維持 | H37: 採用コストゼロで即戦力を配置し長期的な生産体制を構築 | I37: 経営陣 | J37: 代表 | K37: 不明 | L37: 未確認 | Q37: 未開拓 | R37: ターゲット | S37: リストアップ | AH37: 営業推進部 | AI37: 武田 悦郎 | AP37: 未定 | AQ37: =COUNTIFS(加電履歴!$F:$F,B37,加電履歴!$E:$E,"畜種農業") | AR37: =IFERROR(IF(COUNTIFS(加電履歴!$F:$F,B37,加電履歴!$E:$E,"畜種農業")=0,"",MAXIFS(加電履歴!$B:$B,加電履歴!$F:$F,B37,加電履歴!$E:$E,"畜種農業")),"") | AS37: =IFERROR(IF(COUNTIFS(加電履歴!$F:$F,B37,加電履歴!$E:$E,"畜種農業")=0,"",INDEX(加電履歴!$I:$I,MATCH(1,(加電履歴!$F:$F=B37)*(加電履歴!$E:$E="畜種農業")*(加電履歴!$B:$B=MAXIFS(加電履歴!$B:$B,加電履歴!$F:$F,B37,加電履歴!$E:$E,"畜種農業")),0))),"")
A38: 道南 | B38: 有限会社道南アグロ | D38: 北海道茅部郡森町 | E38: 不明 | F38: ひこま豚の生産・販売 | G38: ブランド豚の徹底した飼養管理と人手不足 | H38: きめ細やかな管理作業を即戦力が担いブランド品質の維持に貢献 | I38: 経営陣 | J38: 代表 | K38: 日沼 氏 | L38: 未確認 | Q38: 未開拓 | R38: ターゲット | S38: リストアップ | AH38: 営業推進部 | AI38: 武田 悦郎 | AP38: 未定 | AQ38: =COUNTIFS(加電履歴!$F:$F,B38,加電履歴!$E:$E,"畜種農業") | AR38: =IFERROR(IF(COUNTIFS(加電履歴!$F:$F,B38,加電履歴!$E:$E,"畜種農業")=0,"",MAXIFS(加電履歴!$B:$B,加電履歴!$F:$F,B38,加電履歴!$E:$E,"畜種農業")),"") | AS38: =IFERROR(IF(COUNTIFS(加電履歴!$F:$F,B38,加電履歴!$E:$E,"畜種農業")=0,"",INDEX(加電履歴!$I:$I,MATCH(1,(加電履歴!$F:$F=B38)*(加電履歴!$E:$E="畜種農業")*(加電履歴!$B:$B=MAXIFS(加電履歴!$B:$B,加電履歴!$F:$F,B38,加電履歴!$E:$E,"畜種農業")),0))),"")
... A48: 道南 | B48: 日本フードパッカー株式会社 道南工場 | D48: 北海道 | E48: 不明 | F48: 牛・豚の食肉処理 | G48: 処理工場における慢性的な人員不足 | H48: 食肉加工現場で即戦力となる特定技能人材の配置 | I48: 総務部 | J48: 工場長 | K48: 不明 | L48: 未確認 | Q48: 未開拓 | R48: ターゲット | S48: リストアップ | AH48: 営業推進部 | AI48: 武田 悦郎 | AP48: 未定 | AQ48: =COUNTIFS(加電履歴!$F:$F,B48,加電履歴!$E:$E,"畜種農業") | AR48: =IFERROR(IF(COUNTIFS(加電履歴!$F:$F,B48,加電履歴!$E:$E,"畜種農業")=0,"",MAXIFS(加電履歴!$B:$B,加電履歴!$F:$F,B48,加電履歴!$E:$E,"畜種農業")),"") | AS48: =IFERROR(IF(COUNTIFS(加電履歴!$F:$F,B48,加電履歴!$E:$E,"畜種農業")=0,"",INDEX(加電履歴!$I:$I,MATCH(1,(加電履歴!$F:$F=B48)*(加電履歴!$E:$E="畜種農業")*(加電履歴!$B:$B=MAXIFS(加電履歴!$B:$B,加電履歴!$F:$F,B48,加電履歴!$E:$E,"畜種農業")),0))),"")
A49: 道北 | B49: 株式会社東武牧場 | C49: https://www.facebook.com/Toubufarm/ | D49: 北海道士別市武徳町44線東8号 (〒095-0062) | E49: 0165-23-1548 | F49: 素牛育成専門/常時3200頭飼養 | G49: 年間5000頭の仔牛育成における健康管理 | H49: ルーティン作業を即戦力に任せ観察に注力 | I49: 経営陣 | J49: 代表 | K49: 不明 | L49: 未確認 | Q49: 未開拓 | R49: ターゲット | S49: リストアップ | AG49: 営業推進部 | AH49: 武田 悦郎 | AN49: 未定 | AQ49: =COUNTIFS(加電履歴!$F:$F,B49,加電履歴!$E:$E,"畜種農業") | AR49: =IFERROR(IF(COUNTIFS(加電履歴!$F:$F,B49,加電履歴!$E:$E,"畜種農業")=0,"",MAXIFS(加電履歴!$B:$B,加電履歴!$F:$F,B49,加電履歴!$E:$E,"畜種農業")),"") | AS49: =IFERROR(IF(COUNTIFS(加電履歴!$F:$F,B49,加電履歴!$E:$E,"畜種農業")=0,"",INDEX(加電履歴!$I:$I,MATCH(1,(加電履歴!$F:$F=B49)*(加電履歴!$E:$E="畜種農業")*(加電履歴!$B:$B=MAXIFS(加電履歴!$B:$B,加電履歴!$F:$F,B49,加電履歴!$E:$E,"畜種農業")),0))),"")
A50: 道北 | B50: 株式会社早川牧場 / 有限会社下士別畜産 (もろみ豚 共同販売) | C50: http://www.moromi.co.jp/ | D50: 北海道士別市下士別町41線東3 (早川牧場) / 41線18 (下士別畜産) (〒095-0061) | E50: 0165-22-4157 (早川牧場) / 0165-23-3928 (下士別畜産) | F50: 肉牛生産/独自ブランド | G50: 良質な肉質を保つための飼育管理 | H50: 採用コスト不要の若手人材による基盤強化 | I50: 経営陣 | J50: 代表 | K50: 不明 | L50: 未確認 | Q50: 未開拓 | R50: ターゲット | S50: リストアップ | AG50: 営業推進部 | AH50: 武田 悦郎 | AN50: 未定 | AQ50: =COUNTIFS(加電履歴!$F:$F,B50,加電履歴!$E:$E,"畜種農業") | AR50: =IFERROR(IF(COUNTIFS(加電履歴!$F:$F,B50,加電履歴!$E:$E,"畜種農業")=0,"",MAXIFS(加電履歴!$B:$B,加電履歴!$F:$F,B50,加電履歴!$E:$E,"畜種農業")),"") | AS50: =IFERROR(IF(COUNTIFS(加電履歴!$F:$F,B50,加電履歴!$E:$E,"畜種農業")=0,"",INDEX(加電履歴!$I:$I,MATCH(1,(加電履歴!$F:$F=B50)*(加電履歴!$E:$E="畜種農業")*(加電履歴!$B:$B=MAXIFS(加電履歴!$B:$B,加電履歴!$F:$F,B50,加電履歴!$E:$E,"畜種農業")),0))),"")
A51: 道北 | B51: 美瑛放牧酪農場 (株式会社美瑛ファーム) | C51: http://biei-farm.co.jp/ | D51: 北海道上川郡美瑛町新星平和5235 | E51: 0166-68-6777 | F51: 通年放牧酪農 | G51: 広大な放牧地の管理と業務兼務 | H51: バックヤードの飼育管理を担う人材提供 | I51: 経営陣 | J51: 代表 | K51: 不明 | L51: 未確認 | Q51: 未開拓 | R51: ターゲット | S51: リストアップ | AG51: 営業推進部 | AH51: 武田 悦郎 | AN51: 未定 | AQ51: =COUNTIFS(加電履歴!$F:$F,B51,加電履歴!$E:$E,"畜種農業") | AR51: =IFERROR(IF(COUNTIFS(加電履歴!$F:$F,B51,加電履歴!$E:$E,"畜種農業")=0,"",MAXIFS(加電履歴!$B:$B,加電履歴!$F:$F,B51,加電履歴!$E:$E,"畜種農業")),"") | AS51: =IFERROR(IF(COUNTIFS(加電履歴!$F:$F,B51,加電履歴!$E:$E,"畜種農業")=0,"",INDEX(加電履歴!$I:$I,MATCH(1,(加電履歴!$F:$F=B51)*(加電履歴!$E:$E="畜種農業")*(加電履歴!$B:$B=MAXIFS(加電履歴!$B:$B,加電履歴!$F:$F,B51,加電履歴!$E:$E,"畜種農業")),0))),"")
A52: 道北 | B52: ファームズ千代田 | C52: https://f-chiyoda.com/ | D52: 北海道上川郡美瑛町春日台4221 | E52: 0166-92-7015 | F52: びえい和牛生産・ふれあい牧場 | G52: 畜産・観光の多角化による労働力分散 | H52: 各部門へ柔軟に配置できる特定技能人材 | I52: 経営陣 | J52: 代表 | K52: 不明 | L52: 未確認 | Q52: 未開拓 | R52: ターゲット | S52: リストアップ | AG52: 営業推進部 | AH52: 武田 悦郎 | AN52: 未定 | AQ52: =COUNTIFS(加電履歴!$F:$F,B52,加電履歴!$E:$E,"畜種農業") | AR52: =IFERROR(IF(COUNTIFS(加電履歴!$F:$F,B52,加電履歴!$E:$E,"畜種農業")=0,"",MAXIFS(加電履歴!$B:$B,加電履歴!$F:$F,B52,加電履歴!$E:$E,"畜種農業")),"") | AS52: =IFERROR(IF(COUNTIFS(加電履歴!$F:$F,B52,加電履歴!$E:$E,"畜種農業")=0,"",INDEX(加電履歴!$I:$I,MATCH(1,(加電履歴!$F:$F=B52)*(加電履歴!$E:$E="畜種農業")*(加電履歴!$B:$B=MAXIFS(加電履歴!$B:$B,加電履歴!$F:$F,B52,加電履歴!$E:$E,"畜種農業")),0))),"")
A53: 道北 | B53: 富良野牧場 | C53: https://furanobokujo.com/ | D53: 北海道富良野市東鳥沼1 (〒076-0041) | E53: 0167-22-1543 | F53: 養豚・ハムソーセージ製造 | G53: 製法維持と加工ラインの労働力確保 | H53: 製造加工部門で即戦力となる人材の配置 | I53: 経営陣 | J53: 代表 | K53: 不明 | L53: 未確認 | Q53: 未開拓 | R53: ターゲット | S53: リストアップ | AG53: 営業推進部 | AH53: 武田 悦郎 | AN53: 未定 | AQ53: =COUNTIFS(加電履歴!$F:$F,B53,加電履歴!$E:$E,"畜種農業") | AR53: =IFERROR(IF(COUNTIFS(加電履歴!$F:$F,B53,加電履歴!$E:$E,"畜種農業")=0,"",MAXIFS(加電履歴!$B:$B,加電履歴!$F:$F,B53,加電履歴!$E:$E,"畜種農業")),"") | AS53: =IFERROR(IF(COUNTIFS(加電履歴!$F:$F,B53,加電履歴!$E:$E,"畜種農業")=0,"",INDEX(加電履歴!$I:$I,MATCH(1,(加電履歴!$F:$F=B53)*(加電履歴!$E:$E="畜種農業")*(加電履歴!$B:$B=MAXIFS(加電履歴!$B:$B,加電履歴!$F:$F,B53,加電履歴!$E:$E,"畜種農業")),0))),"")
A54: 道北 | B54: 株式会社サロベツファーム | D54: 北海道天塩郡豊富町字上サロベツ796番地13 | E54: 0162-84-2377 | F54: 食肉加工/独自ブランド | G54: 加工品の生産量維持に伴う人員確保 | H54: 採用コストゼロで加工現場の即戦力を提供 | I54: 経営陣 | J54: 代表 | K54: 不明 | L54: 未確認 | Q54: 未開拓 | R54: ターゲット | S54: リストアップ | AG54: 営業推進部 | AH54: 武田 悦郎 | AN54: 未定 | AQ54: =COUNTIFS(加電履歴!$F:$F,B54,加電履歴!$E:$E,"畜種農業") | AR54: =IFERROR(IF(COUNTIFS(加電履歴!$F:$F,B54,加電履歴!$E:$E,"畜種農業")=0,"",MAXIFS(加電履歴!$B:$B,加電履歴!$F:$F,B54,加電履歴!$E:$E,"畜種農業")),"") | AS54: =IFERROR(IF(COUNTIFS(加電履歴!$F:$F,B54,加電履歴!$E:$E,"畜種農業")=0,"",INDEX(加電履歴!$I:$I,MATCH(1,(加電履歴!$F:$F=B54)*(加電履歴!$E:$E="畜種農業")*(加電履歴!$B:$B=MAXIFS(加電履歴!$B:$B,加電履歴!$F:$F,B54,加電履歴!$E:$E,"畜種農業")),0))),"")
A55: 道北 | B55: 株式会社豊富牛乳公社 | C55: https://www.toyotomi-milk.co.jp/ | D55: 北海道天塩郡豊富町上サロベツ1184 (〒098-4100) | E55: 0162-82-2576 | F55: 豊富牛乳の製造加工 | G55: 製造ラインにおける安定した人員配置 | H55: 工場内の製造を担う定住型人材の提案 | I55: 管理部 | J55: 工場長 | K55: 不明 | L55: 未確認 | Q55: 未開拓 | R55: ターゲット | S55: リストアップ | AG55: 営業推進部 | AH55: 武田 悦郎 | AN55: 未定 | AQ55: =COUNTIFS(加電履歴!$F:$F,B55,加電履歴!$E:$E,"畜種農業") | AR55: =IFERROR(IF(COUNTIFS(加電履歴!$F:$F,B55,加電履歴!$E:$E,"畜種農業")=0,"",MAXIFS(加電履歴!$B:$B,加電履歴!$F:$F,B55,加電履歴!$E:$E,"畜種農業")),"") | AS55: =IFERROR(IF(COUNTIFS(加電履歴!$F:$F,B55,加電履歴!$E:$E,"畜種農業")=0,"",INDEX(加電履歴!$I:$I,MATCH(1,(加電履歴!$F:$F=B55)*(加電履歴!$E:$E="畜種農業")*(加電履歴!$B:$B=MAXIFS(加電履歴!$B:$B,加電履歴!$F:$F,B55,加電履歴!$E:$E,"畜種農業")),0))),"")
A56: 道北 | B56: 日本ハム北海道ファクトリー株式会社 旭川工場 | C56: https://www.nipponham-hokkaidofa.co.jp/ | D56: 北海道旭川市工業団地1条3丁目1番37号 (〒078-8271) | E56: 0166-76-1186 | F56: 食肉加工（美ノ国等） | G56: 年間5,000トン生産体制を支える労働力 | H56: 大規模工場における特定技能の通年雇用 | I56: 総務部 | J56: 工場長 | K56: 不明 | L56: 未確認 | Q56: 未開拓 | R56: ターゲット | S56: リストアップ | AG56: 営業推進部 | AH56: 武田 悦郎 | AN56: 未定 | AQ56: =COUNTIFS(加電履歴!$F:$F,B56,加電履歴!$E:$E,"畜種農業") | AR56: =IFERROR(IF(COUNTIFS(加電履歴!$F:$F,B56,加電履歴!$E:$E,"畜種農業")=0,"",MAXIFS(加電履歴!$B:$B,加電履歴!$F:$F,B56,加電履歴!$E:$E,"畜種農業")),"") | AS56: =IFERROR(IF(COUNTIFS(加電履歴!$F:$F,B56,加電履歴!$E:$E,"畜種農業")=0,"",INDEX(加電履歴!$I:$I,MATCH(1,(加電履歴!$F:$F=B56)*(加電履歴!$E:$E="畜種農業")*(加電履歴!$B:$B=MAXIFS(加電履歴!$B:$B,加電履歴!$F:$F,B56,加電履歴!$E:$E,"畜種農業")),0))),"")
A57: 道北 | B57: 東宗谷農業協同組合 猿払支所/畜産事業所 | C57: https://www.ja-esoya.com/ | D57: 北海道宗谷郡猿払村鬼志別西町51 | E57: 01635-2-3312 (猿払支所代表) | F57: JA運営事業所・公共牧場 | G57: 広大な牧草地の維持・管理 | H57: 公共施設の安定稼働を即戦力で支援 | I57: 畜産部 | J57: 管理者 | K57: 不明 | L57: 未確認 | Q57: 未開拓 | R57: ターゲット | S57: リストアップ | AG57: 営業推進部 | AH57: 武田 悦郎 | AN57: 未定 | AQ57: =COUNTIFS(加電履歴!$F:$F,B57,加電履歴!$E:$E,"畜種農業") | AR57: =IFERROR(IF(COUNTIFS(加電履歴!$F:$F,B57,加電履歴!$E:$E,"畜種農業")=0,"",MAXIFS(加電履歴!$B:$B,加電履歴!$F:$F,B57,加電履歴!$E:$E,"畜種農業")),"") | AS57: =IFERROR(IF(COUNTIFS(加電履歴!$F:$F,B57,加電履歴!$E:$E,"畜種農業")=0,"",INDEX(加電履歴!$I:$I,MATCH(1,(加電履歴!$F:$F=B57)*(加電履歴!$E:$E="畜種農業")*(加電履歴!$B:$B=MAXIFS(加電履歴!$B:$B,加電履歴!$F:$F,B57,加電履歴!$E:$E,"畜種農業")),0))),"")
A58: 道北 | B58: 旭川市営牧場 (嵐山牧場) | C58: https://www.city.asahikawa.hokkaido.jp/500/501/504/p005231.html | D58: 北海道旭川市江丹別町中央 | E58: 0166-73-2451 (現地) / 0166-73-2036 (指定管理者:江丹別産業開発) / 0166-25-7470 (市農政部) | F58: 市営の公共牧場 | G58: 公共施設の放牧管理 | H58: 施設の安定稼働を即戦力で支援 | I58: 農林部 | J58: 管理者 | K58: 不明 | L58: 未確認 | Q58: 未開拓 | R58: ターゲット | S58: リストアップ | AG58: 営業推進部 | AH58: 武田 悦郎 | AN58: 未定 | AQ58: =COUNTIFS(加電履歴!$F:$F,B58,加電履歴!$E:$E,"畜種農業") | AR58: =IFERROR(IF(COUNTIFS(加電履歴!$F:$F,B58,加電履歴!$E:$E,"畜種農業")=0,"",MAXIFS(加電履歴!$B:$B,加電履歴!$F:$F,B58,加電履歴!$E:$E,"畜種農業")),"") | AS58: =IFERROR(IF(COUNTIFS(加電履歴!$F:$F,B58,加電履歴!$E:$E,"畜種農業")=0,"",INDEX(加電履歴!$I:$I,MATCH(1,(加電履歴!$F:$F=B58)*(加電履歴!$E:$E="畜種農業")*(加電履歴!$B:$B=MAXIFS(加電履歴!$B:$B,加電履歴!$F:$F,B58,加電履歴!$E:$E,"畜種農業")),0))),"")
A59: 道北 | B59: 士別市営天塩川牧場 | D59: 北海道士別市 ※詳細要確認、士別市農業振興課が窓口 | E59: 0165-26-7030 (士別市農業振興課) | F59: 市営の育成牧場 | G59: 預託牛の体調管理 | H59: 育成牛の飼養管理をサポート | I59: 農林課 | J59: 管理者 | K59: 不明 | L59: 未確認 | Q59: 未開拓 | R59: ターゲット | S59: リストアップ | AG59: 営業推進部 | AH59: 武田 悦郎 | AN59: 未定 | AQ59: =COUNTIFS(加電履歴!$F:$F,B59,加電履歴!$E:$E,"畜種農業") | AR59: =IFERROR(IF(COUNTIFS(加電履歴!$F:$F,B59,加電履歴!$E:$E,"畜種農業")=0,"",MAXIFS(加電履歴!$B:$B,加電履歴!$F:$F,B59,加電履歴!$E:$E,"畜種農業")),"") | AS59: =IFERROR(IF(COUNTIFS(加電履歴!$F:$F,B59,加電履歴!$E:$E,"畜種農業")=0,"",INDEX(加電履歴!$I:$I,MATCH(1,(加電履歴!$F:$F=B59)*(加電履歴!$E:$E="畜種農業")*(加電履歴!$B:$B=MAXIFS(加電履歴!$B:$B,加電履歴!$F:$F,B59,加電履歴!$E:$E,"畜種農業")),0))),"")
A60: 道北 | B60: 豊富町大規模草地育成牧場 (町営牧場) | D60: 北海道天塩郡豊富町上福永 | E60: 0162-82-2781 | F60: 町営の公共牧場 | G60: 大規模な牧草地の維持 | H60: 採用コスト不要の即戦力人材 | I60: 農林水産課 | J60: 管理者 | K60: 不明 | L60: 未確認 | Q60: 未開拓 | R60: ターゲット | S60: リストアップ | AG60: 営業推進部 | AH60: 武田 悦郎 | AN60: 未定 | AQ60: =COUNTIFS(加電履歴!$F:$F,B60,加電履歴!$E:$E,"畜種農業") | AR60: =IFERROR(IF(COUNTIFS(加電履歴!$F:$F,B60,加電履歴!$E:$E,"畜種農業")=0,"",MAXIFS(加電履歴!$B:$B,加電履歴!$F:$F,B60,加電履歴!$E:$E,"畜種農業")),"") | AS60: =IFERROR(IF(COUNTIFS(加電履歴!$F:$F,B60,加電履歴!$E:$E,"畜種農業")=0,"",INDEX(加電履歴!$I:$I,MATCH(1,(加電履歴!$F:$F=B60)*(加電履歴!$E:$E="畜種農業")*(加電履歴!$B:$B=MAXIFS(加電履歴!$B:$B,加電履歴!$F:$F,B60,加電履歴!$E:$E,"畜種農業")),0))),"")
A61: 道北 | B61: 猿払村営牧場 | D61: 北海道宗谷郡猿払村 (国道238号沿い) | E61: 01635-2-3134 (猿払村産業課) | F61: 村営の公共牧場 | G61: 酪農家からの育成牛管理 | H61: 育成牛管理における人員確保 | I61: 農林課 | J61: 管理者 | K61: 不明 | L61: 未確認 | Q61: 未開拓 | R61: ターゲット | S61: リストアップ | AG61: 営業推進部 | AH61: 武田 悦郎 | AN61: 未定 | AQ61: =COUNTIFS(加電履歴!$F:$F,B61,加電履歴!$E:$E,"畜種農業") | AR61: =IFERROR(IF(COUNTIFS(加電履歴!$F:$F,B61,加電履歴!$E:$E,"畜種農業")=0,"",MAXIFS(加電履歴!$B:$B,加電履歴!$F:$F,B61,加電履歴!$E:$E,"畜種農業")),"") | AS61: =IFERROR(IF(COUNTIFS(加電履歴!$F:$F,B61,加電履歴!$E:$E,"畜種農業")=0,"",INDEX(加電履歴!$I:$I,MATCH(1,(加電履歴!$F:$F=B61)*(加電履歴!$E:$E="畜種農業")*(加電履歴!$B:$B=MAXIFS(加電履歴!$B:$B,加電履歴!$F:$F,B61,加電履歴!$E:$E,"畜種農業")),0))),"")
...

Sheet 加電履歴
A1: No. | B1: 日付 | C1: 開始時刻 | D1: 通話時間(分) | E1: シート | F1: 企業名 | G1: 担当者(自社) | H1: 相手先担当者 | I1: 結果 | J1: 内容メモ | K1: 次回ToDo | L1: 次回予定日
